Workbook

Sheet WIN５ (馬名) (1222_1)
Q2: 45648 | U2: 日曜日
B3: 中山9R | F3: 京都10R | J3: 中山10R | N3: 京都11R | R3: 中山11R
B4: グッドラックハンデ（２５００ｍ） | F4: サンタクロスS（2000ｍ） | J4: オルフェーヴルC（1600ｍ） | N4: りんくうステークス（1200ｍ） | R4: 有馬記念（中山芝2500ｍ）
B5: 馬番 | C5: 人気 | D5: 人気順 | E5: １回目 | F5: 馬番 | G5: 人気 | H5: 人気順 | I5: ２回目 | J5: 馬番 | K5: 人気 | L5: 人気順 | M5: ３回目 | N5: 馬番 | O5: 人気 | P5: 人気順 | Q5: ４回目 | R5: 馬番 | S5: 人気 | T5: 人気順 | U5: ５回目
D6: 1 | E6: アイザックバローズ57川田将雅 | H6: 1 | I6: エラトー牝３ | L6: 1 | M6: アーレンダール牝５ | P6: 1 | Q6: エランティス55牝４ | R6: 1 | T6: 1 | U6: ダノンデサイル横山典弘
D7: 2 | E7: アバンデル55 | H7: 2 | I7: エリダヌス牝４ | L7: 2 | M7: ウインアイオライト牝４T.マーカンド | P7: 2 | Q7: エーティーマクフィ57 | R7: 2 | T7: 2 | U7: ドゥデュース武豊
D8: 3 | E8: ウインマイルート56H.ドイル | H8: 3 | I8: ガイアメンテ | L8: 3 | M8: ウインレイアー牝４Ｈ．ドイル | P8: 3 | Q8: オメガシンフォニー55牝４ | R8: 3 | T8: 3 | U8: アーバンシックＣ．ルメール
D9: 4 | E9: オリエンタルナイト54戸崎圭太 | H9: 4 | I9: ゲンパチムサシ | L9: 4 | M9: ケイケイ騙3 | P9: 4 | Q9: カルネアサーダ56牝５ | R9: 4 | T9: 4 | U9: ブローザホーン菅原明良
D10: 5 | E10: カナオールウェイズ54C.デムーロ | H10: 5 | I10: シャザーン | L10: 5 | M10: サロニコスC.デムーロ | P10: 5 | Q10: クリノマジン57 | R10: 5 | T10: 5 | U10: ベラジオオペラ横山和生
D11: 6 | E11: グランアルティスタ55武豊 | H11: 6 | I11: シュタールヴィント | L11: 6 | M11: ジッピーレーサー | P11: 6 | Q11: ジャングロ59団野大成 | R11: 6 | T11: 6 | U11: ローシャムパークT.マーカンド
D12: 7 | E12: サンライズソレイユ55坂井瑠星 | H12: 7 | I12: セレブレイトガイズ | L12: 7 | M12: ツルマウカタチ | P12: 7 | Q12: ジョーローリット54M.デムーロ | R12: 7 | T12: 7 | U12: スターズオンアース川田将雅
D13: 8 | E13: シュプリーム54 | H13: 8 | I13: ドットクルー | L13: 8 | M13: トーセントラム | P13: 8 | Q13: スターターン56 | R13: 8 | T13: 8 | U13: レガレイラ戸崎圭太
D14: 9 | E14: スズノマーベリック55騙8 | H14: 9 | I14: ニホンピロタイズ | L14: 9 | M14: ハワイアンタイム 騙４ | P14: 9 | Q14: ダノンセシボン55牝４ | R14: 9 | T14: 9 | U14: ディープボンド幸英明
D15: 10 | E15: スティンガーグラス56C.ルメール | H15: 10 | I15: ニューノーマル牝5 | L15: 10 | M15: ピックアチェリー牝３ | P15: 10 | Q15: ドンアミティエ57 | R15: 10 | T15: 10 | U15: プログノーシス三浦皇成
D16: 11 | E16: スピーディブレイク55T.マーカンド | H16: 11 | I16: ホウオウプロサンゲ | L16: 11 | M16: ブルトンクール牝５ | P16: 11 | Q16: ハチメンロッピ57 | R16: 11 | T16: 11 | U16: ジャスティンパレス坂井瑠星
D17: 12 | E17: ノーブルクライ56 | H17: 12 | I17: モズロックンロール | L17: 12 | M17: ユキノロイヤル | P17: 12 | Q17: パラシュラーマ57 | R17: 12 | T17: 12 | U17: シュトルーヴェ鮫島克駿
... D19: 14 | E19: プレイリードリーム56 | H19: 14 | I19: ワイドアラジン団野大成 | L19: 14 | M19: ラレーヌデリス牝４戸崎圭太 | P19: 14 | Q19: ボナンザ57 | R19: 14 | T19: 14 | U19: ダノンベルーガ松山弘平
D20: 15 | E20: フロムナウオン55 | H20: 15 | L20: 15 | M20: ルージュイストリア牝４ | P20: 15 | Q20: メズメライザー57騙5 | R20: 15 | T20: 15 | U20: ハヤヤッコ吉田豊
D21: 16 | E21: ホウオウサンデー | H21: 16 | L21: 16 | M21: ロゼル | P21: 16 | Q21: ロードラディウス57 | R21: 16 | T21: 16 | U21: シャフリヤールC.デムーロ
D22: 17 | H22: 17 | L22: 17 | P22: 17 | R22: 17 | T22: 17
D23: 18 | H23: 18 | L23: 18 | P23: 18 | R23: 18 | T23: 18

Sheet オッズデータ入力
A1: 46096 | F1: 日曜日 | AD1: WIN５
A2: 締切：14時45分 | F2: =NOW() | O2: ★★★
B3: WIN１ | G3: 1 | H3: 2 | I3: 3 | N3: WIN2 | S3: 1 | T3: 2 | U3: 3 | V3: 4 | W3: 5 | X3: 6 | Y3: 7 | Z3: WIN3 | AE3: 1 | AF3: 2 | AG3: 3 | AH3: 4 | AI3: 5 | AJ3: 6 | AK3: 7 | AL3: WIN4 ハンデ | AQ3: 1 | AR3: 2 | AS3: 3 | AT3: 4 | AU3: 5 | AV3: 6 | AW3: 7 | AX3: WIN5 | BC3: 1 | BD3: 2 | BE3: 3 | BF3: 4 | BG3: 5 | BH3: 6 | BI3: 7
A4: ランク | B4: 0.61805556 | G4: 性齢 | H4: 斤量 | I4: 騎手名 | N4: 0.625 | S4: 性齢 | T4: 斤量 | U4: 騎手名 | Z4: 0.63541667 | AE4: 性齢 | AF4: 斤量 | AG4: 騎手名 | AL4: 0.64583333 | AQ4: 性齢 | AR4: 斤量 | AS4: 騎手名 | AX4: 0.65625 | BC4: 性齢 | BD4: 斤量 | BE4: 騎手名
B5: 中山10R_スピカS | N5: 阪神10R_レグルスS | Z5: 中京11R_愛知杯 | AL5: 中山11R_千葉S | AX5: 阪神11R_阪神大賞典
B6: 4歳以上3勝クラス（混合）1,800メートル（芝・右） | N6: 4歳以上オープン1,800メートル（ダート・右） | Z6: 4歳以上牝1,400メートル（芝・左） | AL6: 4歳以上オープンハンデ 1,200メートル（ダート・右） | AX6: 4歳以上オープン3,000メートル（芝・右）
B7: 差 | C7: 人気順 | D7: 馬番 | E7: オッズ | F7: 馬名等 | N7: 差 | O7: 人気順 | P7: 馬番 | Q7: オッズ | R7: 馬名等 | Z7: 差 | AA7: 人気順 | AB7: 馬番 | AC7: オッズ | AD7: 馬名等 | AL7: 差 | AM7: 人気順 | AN7: 馬番 | AO7: オッズ | AP7: 馬名等 | AX7: 差 | AY7: 人気順 | AZ7: 馬番 | BA7: オッズ | BB7: 馬名等
A8: A | B8: =E8/E7 | C8: =IFERROR(RANK(E8, E$8:E$25, 1),"") | D8: 8 | E8: 2.4 | F8: エストゥペンダ | G8: 牝4 | H8: 56 | I8: 戸崎圭 | N8: =Q8/Q7 | O8: =IFERROR(RANK(Q8, Q$8:Q$25, 1),"") | P8: 8 | Q8: 3.6 | R8: ルシュヴァルドール | S8: 牡5 | T8: 60 | U8: 坂井 | Z8: =AC8/AC7 | AA8: =IFERROR(RANK(AC8, AC$8:AC$25, 1),"") | AB8: 1 | AC8: 5.3 | AD8: マピュース | AE8: 牝4 | AF8: 56 | AG8: 田辺 | AL8: =AO8/AO7 | AM8: =IFERROR(RANK(AO8, AO$8:AO$25, 1),"") | AN8: 14 | AO8: 3.6 | AP8: エコロアゼル | AQ8: 牡4 | AR8: 57 | AS8: 岩田康 | AX8: =BA8/BA7 | AY8: =IFERROR(RANK(BA8, BA$8:BA$25, 1),"") | AZ8: 1 | BA8: 3 | BB8: アドマイヤテラ | BC8: 牡5 | BD8: 58 | BE8: 武豊 | BF8: 戸崎圭
B9: =E9/E8 | C9: =IFERROR(RANK(E9, E$8:E$25, 1),"") | D9: 5 | E9: 3.7 | F9: フィーリウス | G9: 牡4 | H9: 58 | I9: 津村 | N9: =Q9/Q8 | O9: =IFERROR(RANK(Q9, Q$8:Q$25, 1),"") | P9: 7 | Q9: 4.2 | R9: タガノバビロン | S9: 牡4 | T9: 58 | U9: 松山 | Z9: =AC9/AC8 | AA9: =IFERROR(RANK(AC9, AC$8:AC$25, 1),"") | AB9: 7 | AC9: 5.9 | AD9: チェルビアット | AE9: 牝4 | AF9: 55 | AG9: 西村淳 | AL9: =AO9/AO8 | AM9: =IFERROR(RANK(AO9, AO$8:AO$25, 1),"") | AN9: 10 | AO9: 4.5 | AP9: ドラゴンウェルズ | AQ9: 牡4 | AR9: 56 | AS9: 戸崎圭 | AX9: =BA9/BA8 | AY9: =IFERROR(RANK(BA9, BA$8:BA$25, 1),"") | AZ9: 5 | BA9: 3.4 | BB9: ダノンシーマ | BC9: 牡4 | BD9: 56 | BE9: 川田 | BF9: ルメール
A10: B | B10: =E10/E9 | C10: =IFERROR(RANK(E10, E$8:E$25, 1),"") | D10: 4 | E10: 4.4 | F10: ジュタ | G10: 牡4 | H10: 58 | I10: 岩田康 | N10: =Q10/Q9 | O10: =IFERROR(RANK(Q10, Q$8:Q$25, 1),"") | P10: 11 | Q10: 7.5 | R10: ジンセイ | S10: 牡5 | T10: 58 | U10: 川田 | Z10: =AC10/AC9 | AA10: =IFERROR(RANK(AC10, AC$8:AC$25, 1),"") | AB10: 16 | AC10: 6.3 | AD10: ドロップオブライト | AE10: 牝7 | AF10: 56 | AG10: 松若 | AL10: =AO10/AO9 | AM10: =IFERROR(RANK(AO10, AO$8:AO$25, 1),"") | AN10: 12 | AO10: 6 | AP10: メイショウホウレン | AQ10: 牡5 | AR10: 57 | AS10: 菊沢 | AX10: =BA10/BA9 | AY10: =IFERROR(RANK(BA10, BA$8:BA$25, 1),"") | AZ10: 6 | BA10: 4.7 | BB10: レッドバンデ | BC10: 牡4 | BD10: 56 | BE10: 佐々木 | BF10: 佐々木
B11: =E11/E10 | C11: =IFERROR(RANK(E11, E$8:E$25, 1),"") | D11: 7 | E11: 8.2 | F11: ドゥカート | G11: 牡4 | H11: 58 | I11: 菊沢 | N11: =Q11/Q10 | O11: =IFERROR(RANK(Q11, Q$8:Q$25, 1),"") | P11: 5 | Q11: 7.7 | R11: モックモック | S11: 牡6 | T11: 58 | U11: 武豊 | Z11: =AC11/AC10 | AA11: =IFERROR(RANK(AC11, AC$8:AC$25, 1),"") | AB11: 5 | AC11: 7.2 | AD11: ウイントワイライト | AE11: 牝4 | AF11: 55 | AG11: 横山典 | AL11: =AO11/AO10 | AM11: =IFERROR(RANK(AO11, AO$8:AO$25, 1),"") | AN11: 7 | AO11: 9.2 | AP11: エートラックス | AQ11: 牡5 | AR11: 58.5 | AS11: ルメール | AX11: =BA11/BA10 | AY11: =IFERROR(RANK(BA11, BA$8:BA$25, 1),"") | AZ11: 7 | BA11: 7.2 | BB11: マイネルエンペラー | BC11: 牡6 | BD11: 58 | BE11: 丹内 | BF11: 鮫島駿
B12: =E12/E11 | C12: =IFERROR(RANK(E12, E$8:E$25, 1),"") | D12: 2 | E12: 12.4 | F12: エラン | G12: 牡5 | H12: 58 | I12: 荻野極 | N12: =Q12/Q11 | O12: =IFERROR(RANK(Q12, Q$8:Q$25, 1),"") | P12: 9 | Q12: 10.2 | R12: ハギノサステナブル | S12: 牡6 | T12: 58 | U12: 北村友 | Z12: =AC12/AC11 | AA12: =IFERROR(RANK(AC12, AC$8:AC$25, 1),"") | AB12: 15 | AC12: 10.9 | AD12: ワイドラトゥール | AE12: 牝5 | AF12: 56 | AG12: 西塚 | AL12: =AO12/AO11 | AM12: =IFERROR(RANK(AO12, AO$8:AO$25, 1),"") | AN12: 6 | AO12: 9.8 | AP12: ルディック | AQ12: 牡5 | AR12: 55 | AS12: 津村 | AX12: =BA12/BA11 | AY12: =IFERROR(RANK(BA12, BA$8:BA$25, 1),"") | AZ12: 3 | BA12: 8.9 | BB12: ファミリータイム | BC12: 牡5 | BD12: 57 | BE12: 松山 | BF12: 松若
A13: C | B13: =E13/E12 | C13: =IFERROR(RANK(E13, E$8:E$25, 1),"") | D13: 6 | E13: 19.3 | F13: モズロックンロール | G13: 牡6 | H13: 58 | I13: 横山琉 | N13: =Q13/Q12 | O13: =IFERROR(RANK(Q13, Q$8:Q$25, 1),"") | P13: 6 | Q13: 11.2 | R13: メイショウズイウン | S13: 牡4 | T13: 58 | U13: 太宰 | Z13: =AC13/AC12 | AA13: =IFERROR(RANK(AC13, AC$8:AC$25, 1),"") | AB13: 6 | AC13: 12.9 | AD13: ナムラクララ | AE13: 牝4 | AF13: 55 | AG13: 浜中 | AL13: =AO13/AO12 | AM13: =IFERROR(RANK(AO13, AO$8:AO$25, 1),"") | AN13: 13 | AO13: 15 | AP13: エコロガイア | AQ13: 牡5 | AR13: 55 | AS13: 高倉 | AX13: =BA13/BA12 | AY13: =IFERROR(RANK(BA13, BA$8:BA$25, 1),"") | AZ13: 4 | BA13: 10.6 | BB13: アクアヴァーナル | BC13: 牝5 | BD13: 55 | BE13: 坂井 | BF13: 津村
B14: =E14/E13 | C14: =IFERROR(RANK(E14, E$8:E$25, 1),"") | D14: 1 | E14: 19.6 | F14: アマイ | G14: 牝6 | H14: 56 | I14: 原 | N14: =Q14/Q13 | O14: =IFERROR(RANK(Q14, Q$8:Q$25, 1),"") | P14: 16 | Q14: 14.5 | R14: ロードラビリンス | S14: 牡4 | T14: 58 | U14: 鮫島駿 | Z14: =AC14/AC13 | AA14: =IFERROR(RANK(AC14, AC$8:AC$25, 1),"") | AB14: 8 | AC14: 15.1 | AD14: ソルトクィーン | AE14: 牝5 | AF14: 55 | AG14: 富田 | AL14: =AO14/AO13 | AM14: =IFERROR(RANK(AO14, AO$8:AO$25, 1),"") | AN14: 3 | AO14: 16.5 | AP14: アガシ | AQ14: セ5 | AR14: 55 | AS14: 三浦 | AX14: =BA14/BA13 | AY14: =IFERROR(RANK(BA14, BA$8:BA$25, 1),"") | AZ14: 2 | BA14: 32.5 | BB14: シュヴァリエローズ | BC14: 牡8 | BD14: 57 | BE14: 北村友 | BF14: プーシャン
B15: =E15/E14 | C15: =IFERROR(RANK(E15, E$8:E$25, 1),"") | D15: 9 | E15: 31.5 | F15: マイネルトルファン | G15: 牡7 | H15: 58 | I15: 柴田大 | N15: =Q15/Q14 | O15: =IFERROR(RANK(Q15, Q$8:Q$25, 1),"") | P15: 15 | Q15: 19.2 | R15: タイトニット | S15: 牡6 | T15: 59 | U15: 丹内 | Z15: =AC15/AC14 | AA15: =IFERROR(RANK(AC15, AC$8:AC$25, 1),"") | AB15: 2 | AC15: 15.2 | AD15: レディマリオン | AE15: 牝5 | AF15: 55 | AG15: 吉村 | AL15: =AO15/AO14 | AM15: =IFERROR(RANK(AO15, AO$8:AO$25, 1),"") | AN15: 4 | AO15: 18.4 | AP15: ユキマル | AQ15: 牡6 | AR15: 55 | AS15: 木幡巧 | AX15: =BA15/BA14 | AY15: =IFERROR(RANK(BA15, BA$8:BA$25, 1),"") | AZ15: 9 | BA15: 37.9 | BB15: サンライズソレイユ | BC15: 牡5 | BD15: 57 | BE15: 岩田望 | BF15: 菅原明
A16: D | B16: =E16/E15 | C16: =IFERROR(RANK(E16, E$8:E$25, 1),"") | D16: 3 | E16: 180.8 | F16: レディベル | G16: 牝7 | H16: 56 | I16: 石川 | N16: =Q16/Q15 | O16: =IFERROR(RANK(Q16, Q$8:Q$25, 1),"") | P16: 4 | Q16: 25.7 | R16: テーオーグランビル | S16: 牡6 | T16: 58 | U16: 岩田望 | Z16: =AC16/AC15 | AA16: =IFERROR(RANK(AC16, AC$8:AC$25, 1),"") | AB16: 12 | AC16: 18.3 | AD16: カルプスペルシュ | AE16: 牝4 | AF16: 55 | AG16: 横山武 | AL16: =AO16/AO15 | AM16: =IFERROR(RANK(AO16, AO$8:AO$25, 1),"") | AN16: 9 | AO16: 19.1 | AP16: ブレーザー | AQ16: 牡5 | AR16: 55 | AS16: 荻野極 | AX16: =BA16/BA15 | AY16: =IFERROR(RANK(BA16, BA$8:BA$25, 1),"") | AZ16: 8 | BA16: 88.1 | BB16: メイショウブレゲ | BC16: 牡7 | BD16: 57 | BE16: 酒井 | BF16: 吉田豊
B17: =E17/E16 | C17: =IFERROR(RANK(E17, E$8:E$25, 1),"") | N17: =Q17/Q16 | O17: =IFERROR(RANK(Q17, Q$8:Q$25, 1),"") | P17: 2 | Q17: 28.9 | R17: シュラザック | S17: 牡4 | T17: 58 | U17: 田口 | Z17: =AC17/AC16 | AA17: =IFERROR(RANK(AC17, AC$8:AC$25, 1),"") | AB17: 11 | AC17: 22.5 | AD17: スリールミニョン | AE17: 牝4 | AF17: 55 | AG17: 丸山 | AL17: =AO17/AO16 | AM17: =IFERROR(RANK(AO17, AO$8:AO$25, 1),"") | AN17: 15 | AO17: 22.7 | AP17: ショウナンアビアス | AQ17: 牡6 | AR17: 55 | AS17: 柴田善 | AX17: =BA17/BA16 | AY17: =IFERROR(RANK(BA17, BA$8:BA$25, 1),"") | AZ17: 10 | BA17: 96 | BB17: ダンディズム | BC17: セ10 | BD17: 57 | BE17: 松本 | BF17: 荻野極
B18: =E18/E17 | C18: =IFERROR(RANK(E18, E$8:E$25, 1),"") | N18: =Q18/Q17 | O18: =IFERROR(RANK(Q18, Q$8:Q$25, 1),"") | P18: 10 | Q18: 32.3 | R18: レッドプロフェシー | S18: 牡6 | T18: 58 | U18: 酒井 | Z18: =AC18/AC17 | AA18: =IFERROR(RANK(AC18, AC$8:AC$25, 1),"") | AB18: 18 | AC18: 22.6 | AD18: アイサンサン | AE18: 牝4 | AF18: 55 | AG18: 幸 | AL18: =AO18/AO17 | AM18: =IFERROR(RANK(AO18, AO$8:AO$25, 1),"") | AN18: 8 | AO18: 48.8 | AP18: シークレットヴァウ | AQ18: 牡5 | AR18: 55 | AS18: 武藤 | AX18: =BA18/BA17 | AY18: =IFERROR(RANK(BA18, BA$8:BA$25, 1),"") | BF18: マーカンド
A19: E | B19: =E19/E18 | C19: =IFERROR(RANK(E19, E$8:E$25, 1),"") | N19: =Q19/Q18 | O19: =IFERROR(RANK(Q19, Q$8:Q$25, 1),"") | P19: 1 | Q19: 42.4 | R19: カペルブリュッケ | S19: 牡4 | T19: 58 | U19: 斎藤 | Z19: =AC19/AC18 | AA19: =IFERROR(RANK(AC19, AC$8:AC$25, 1),"") | AB19: 17 | AC19: 23 | AD19: リラボニート | AE19: 牝5 | AF19: 55 | AG19: 田山 | AL19: =AO19/AO18 | AM19: =IFERROR(RANK(AO19, AO$8:AO$25, 1),"") | AN19: 5 | AO19: 58.3 | AP19: ロードフロンティア | AQ19: 牡5 | AR19: 55 | AS19: 原 | AX19: =BA19/BA18 | AY19: =IFERROR(RANK(BA19, BA$8:BA$25, 1),"") | BF19: 石橋脩
B20: =E20/E19 | C20: =IFERROR(RANK(E20, E$8:E$25, 1),"") | N20: =Q20/Q19 | O20: =IFERROR(RANK(Q20, Q$8:Q$25, 1),"") | P20: 3 | Q20: 67 | R20: グーデンドラーク | S20: 牡7 | T20: 58 | U20: 国分優 | Z20: =AC20/AC19 | AA20: =IFERROR(RANK(AC20, AC$8:AC$25, 1),"") | AB20: 13 | AC20: 30.7 | AD20: アブキールベイ | AE20: 牝4 | AF20: 56 | AG20: 小崎 | AL20: =AO20/AO19 | AM20: =IFERROR(RANK(AO20, AO$8:AO$25, 1),"") | AN20: 2 | AO20: 59.6 | AP20: テイエムトッキュウ | AQ20: 牡8 | AR20: 58.5 | AS20: 石橋脩 | AX20: =BA20/BA19 | AY20: =IFERROR(RANK(BA20, BA$8:BA$25, 1),"") | BF20: 石川
B21: =E21/E20 | C21: =IFERROR(RANK(E21, E$8:E$25, 1),"") | N21: =Q21/Q20 | O21: =IFERROR(RANK(Q21, Q$8:Q$25, 1),"") | P21: 14 | Q21: 111.8 | R21: メイショウユズルハ | S21: 牡7 | T21: 58 | U21: 菱田 | Z21: =AC21/AC20 | AA21: =IFERROR(RANK(AC21, AC$8:AC$25, 1),"") | AB21: 10 | AC21: 31.4 | AD21: セフィロ | AE21: 牝6 | AF21: 55 | AG21: 吉田隼 | AL21: =AO21/AO20 | AM21: =IFERROR(RANK(AO21, AO$8:AO$25, 1),"") | AN21: 11 | AO21: 66.6 | AP21: ムーヴ | AQ21: 牡7 | AR21: 55 | AS21: 横山琉 | AX21: =BA21/BA20 | AY21: =IFERROR(RANK(BA21, BA$8:BA$25, 1),"") | BF21: 菅原隆
A22: F | B22: =E22/E21 | C22: =IFERROR(RANK(E22, E$8:E$25, 1),"") | N22: =Q22/Q21 | O22: =IFERROR(RANK(Q22, Q$8:Q$25, 1),"") | P22: 12 | Q22: 121.4 | R22: ピースオブザライフ | S22: 牝6 | T22: 56 | U22: 松本 | Z22: =AC22/AC21 | AA22: =IFERROR(RANK(AC22, AC$8:AC$25, 1),"") | AB22: 3 | AC22: 55.2 | AD22: モリノドリーム | AE22: 牝7 | AF22: 55 | AG22: 小林美 | AL22: =AO22/AO21 | AM22: =IFERROR(RANK(AO22, AO$8:AO$25, 1),"") | AN22: 16 | AO22: 83.6 | AP22: ケイアイドリー | AQ22: 牡9 | AR22: 58.5 | AS22: 藤懸 | AX22: =BA22/BA21 | AY22: =IFERROR(RANK(BA22, BA$8:BA$25, 1),"")
B23: =E23/E22 | C23: =IFERROR(RANK(E23, E$8:E$25, 1),"") | N23: =Q23/Q22 | O23: =IFERROR(RANK(Q23, Q$8:Q$25, 1),"") | P23: 13 | Q23: 187.4 | R23: ラインオブソウル | S23: 牡7 | T23: 58 | U23: 角田和 | Z23: =AC23/AC22 | AA23: =IFERROR(RANK(AC23, AC$8:AC$25, 1),"") | AB23: 14 | AC23: 68.8 | AD23: シンバーシア | AE23: 牝5 | AF23: 55 | AG23: 団野 | AL23: =AO23/AO22 | AM23: =IFERROR(RANK(AO23, AO$8:AO$25, 1),"") | AN23: 1 | AO23: 120.1 | AP23: ジャスパーゴールド | AQ23: セ8 | AR23: 55 | AS23: 松岡 | AX23: =BA23/BA22 | AY23: =IFERROR(RANK(BA23, BA$8:BA$25, 1),"")
B24: =E24/E23 | C24: =IFERROR(RANK(E24, E$8:E$25, 1),"") | N24: =Q24/Q23 | O24: =IFERROR(RANK(Q24, Q$8:Q$25, 1),"") | P24: =IFERROR(RANK(Q24, Q$8:Q$25, 1),"") | Z24: =AC24/AC23 | AA24: =IFERROR(RANK(AC24, AC$8:AC$25, 1),"") | AB24: 9 | AC24: 89.8 | AD24: マサノカナリア | AE24: 牝5 | AF24: 55 | AG24: 古川吉 | AL24: =AO24/AO23 | AM24: =IFERROR(RANK(AO24, AO$8:AO$25, 1),"") | AX24: =BA24/BA23 | AY24: =IFERROR(RANK(BA24, BA$8:BA$25, 1),"") | AZ24: =IFERROR(RANK(BA24, BA$8:BA$25, 1),"")
A25: G | B25: =E25/E24 | C25: =IFERROR(RANK(E25, E$8:E$25, 1),"") | N25: =Q25/Q24 | O25: =IFERROR(RANK(Q25, Q$8:Q$25, 1),"") | P25: =IFERROR(RANK(Q25, Q$8:Q$25, 1),"") | Z25: =AC25/AC24 | AA25: =IFERROR(RANK(AC25, AC$8:AC$25, 1),"") | AB25: 4 | AC25: 132 | AD25: カンパニョーラ | AE25: 牝7 | AF25: 55 | AG25: 嶋田 | AL25: =AO25/AO24 | AM25: =IFERROR(RANK(AO25, AO$8:AO$25, 1),"") | AX25: =BA25/BA24 | AY25: =IFERROR(RANK(BA25, BA$8:BA$25, 1),"") | AZ25: =IFERROR(RANK(BA25, BA$8:BA$25, 1),"")
A27: 平均オッズ | E27: =AVERAGE(E8:E25) | Q27: =AVERAGE(Q8:Q26) | AC27: =AVERAGE(AC8:AC26) | AO27: =AVERAGE(AO8:AO26) | BA27: =AVERAGE(BA8:BA26)
E29: １レース目 | Q29: ２レース目 | AC29: ３レース目 | AO29: ４レース目 | BA29: ５レース目
E30: 1 | F30: 中央競馬予想隊 | Q30: 1 | R30: 中央競馬予想隊 | AC30: 1 | AD30: 中央競馬予想隊 | AO30: 1 | AP30: 中央競馬予想隊 | BA30: 1 | BB30: 中央競馬予想隊
E31: 2 | F31: 消・買 | Q31: 2 | R31: 消・買 | AC31: 2 | AD31: 消・買 | AO31: 2 | AP31: 消・買 | BA31: 2 | BB31: 消・買
E32: 3 | F32: おじさんの予想 | Q32: 3 | R32: おじさんの予想 | AC32: 3 | AD32: おじさんの予想 | AO32: 3 | AP32: おじさんの予想 | BA32: 3 | BB32: おじさんの予想
E33: 4 | F33: 統計分析 | Q33: 4 | R33: 統計分析 | AC33: 4 | AD33: 統計分析 | AO33: 4 | AP33: 統計分析 | BA33: 4 | BB33: 統計分析
E34: 5 | F34: NUNO競馬 | Q34: 5 | R34: NUNO競馬 | AC34: 5 | AD34: NUNO競馬 | AO34: 5 | AP34: NUNO競馬 | BA34: 5 | BB34: NUNO競馬
E35: 6 | F35: ムーケン | Q35: 6 | R35: ムーケン | AC35: 6 | AD35: ムーケン | AO35: 6 | AP35: ムーケン | BA35: 6 | BB35: ムーケン

Sheet 2回
B2: WIN1 | D2: WIN2 | F2: WIN3 | H2: WIN4 | J2: WIN5 | L2: WIN1 | M2: WIN2 | N2: WIN3 | O2: WIN4 | P2: WIN5 | Q2: WIN1 | R2: WIN2 | S2: WIN3 | T2: WIN4 | U2: WIN5 | V2: 人気の和 | W2: 人気の和
A3: 1 | B3: 1 | C3: =VLOOKUP(B3,オッズデータ入力!C$7:D$25,2,FALSE) | D3: 1 | E3: =VLOOKUP(D3,オッズデータ入力!O$7:P$25,2,FALSE) | L3: =IF(B3<=2,"A",IF(B3<=5,"B",IF(B3<=7,"C",IF(B3<=10,"D",IF(B3<=13,"E",IF(B3<=16,"F",IF(B3<=18,"G"))))))) | M3: =IF(D3<=2,"A",IF(D3<=5,"B",IF(D3<=7,"C",IF(D3<=10,"D",IF(D3<=13,"E",IF(D3<=16,"F",IF(D3<=18,"G"))))))) | Q3: =C3 | R3: =E3 | V3: 14~20 | W3: =SUM(B3,D3,F3,H3,J3) | X3: +
A4: 2 | B4: 1 | C4: =VLOOKUP(B4,オッズデータ入力!C$7:D$25,2,FALSE) | D4: 2 | E4: =VLOOKUP(D4,オッズデータ入力!O$7:P$25,2,FALSE) | L4: =IF(B4<=2,"A",IF(B4<=5,"B",IF(B4<=7,"C",IF(B4<=10,"D",IF(B4<=13,"E",IF(B4<=16,"F",IF(B4<=18,"G"))))))) | M4: =IF(D4<=2,"A",IF(D4<=5,"B",IF(D4<=7,"C",IF(D4<=10,"D",IF(D4<=13,"E",IF(D4<=16,"F",IF(D4<=18,"G"))))))) | Q4: =C4 | R4: =E4 | V4: 14~20 | W4: =SUM(B4,D4,F4,H4,J4) | X4: +
A5: 3 | B5: 2 | C5: =VLOOKUP(B5,オッズデータ入力!C$7:D$25,2,FALSE) | D5: 1 | E5: =VLOOKUP(D5,オッズデータ入力!O$7:P$25,2,FALSE) | L5: =IF(B5<=2,"A",IF(B5<=5,"B",IF(B5<=7,"C",IF(B5<=10,"D",IF(B5<=13,"E",IF(B5<=16,"F",IF(B5<=18,"G"))))))) | M5: =IF(D5<=2,"A",IF(D5<=5,"B",IF(D5<=7,"C",IF(D5<=10,"D",IF(D5<=13,"E",IF(D5<=16,"F",IF(D5<=18,"G"))))))) | Q5: =C5 | R5: =E5 | V5: 14~20 | W5: =SUM(B5,D5,F5,H5,J5) | X5: +
A6: 4 | B6: 2 | C6: =VLOOKUP(B6,オッズデータ入力!C$7:D$25,2,FALSE) | D6: 2 | E6: =VLOOKUP(D6,オッズデータ入力!O$7:P$25,2,FALSE) | L6: =IF(B6<=2,"A",IF(B6<=5,"B",IF(B6<=7,"C",IF(B6<=10,"D",IF(B6<=13,"E",IF(B6<=16,"F",IF(B6<=18,"G"))))))) | M6: =IF(D6<=2,"A",IF(D6<=5,"B",IF(D6<=7,"C",IF(D6<=10,"D",IF(D6<=13,"E",IF(D6<=16,"F",IF(D6<=18,"G"))))))) | Q6: =C6 | R6: =E6 | V6: 14~20 | W6: =SUM(B6,D6,F6,H6,J6) | X6: +
A7: 5 | B7: 1 | C7: =VLOOKUP(B7,オッズデータ入力!C$7:D$25,2,FALSE) | F7: 1 | G7: =VLOOKUP(F7,オッズデータ入力!AA$7:AB$25,2,FALSE) | L7: =IF(B7<=2,"A",IF(B7<=5,"B",IF(B7<=7,"C",IF(B7<=10,"D",IF(B7<=13,"E",IF(B7<=16,"F",IF(B7<=18,"G"))))))) | N7: =IF(F7<=2,"A",IF(F7<=5,"B",IF(F7<=7,"C",IF(F7<=10,"D",IF(F7<=13,"E",IF(F7<=16,"F",IF(F7<=18,"G"))))))) | Q7: =C7 | S7: =G7 | V7: 14~20 | W7: =SUM(B7,D7,F7,H7,J7) | X7: +
A8: 6 | B8: 1 | C8: =VLOOKUP(B8,オッズデータ入力!C$7:D$25,2,FALSE) | F8: 2 | G8: =VLOOKUP(F8,オッズデータ入力!AA$7:AB$25,2,FALSE) | L8: =IF(B8<=2,"A",IF(B8<=5,"B",IF(B8<=7,"C",IF(B8<=10,"D",IF(B8<=13,"E",IF(B8<=16,"F",IF(B8<=18,"G"))))))) | N8: =IF(F8<=2,"A",IF(F8<=5,"B",IF(F8<=7,"C",IF(F8<=10,"D",IF(F8<=13,"E",IF(F8<=16,"F",IF(F8<=18,"G"))))))) | Q8: =C8 | S8: =G8 | V8: 14~20 | W8: =SUM(B8,D8,F8,H8,J8) | X8: +
A9: 7 | B9: 2 | C9: =VLOOKUP(B9,オッズデータ入力!C$7:D$25,2,FALSE) | F9: 1 | G9: =VLOOKUP(F9,オッズデータ入力!AA$7:AB$25,2,FALSE) | L9: =IF(B9<=2,"A",IF(B9<=5,"B",IF(B9<=7,"C",IF(B9<=10,"D",IF(B9<=13,"E",IF(B9<=16,"F",IF(B9<=18,"G"))))))) | N9: =IF(F9<=2,"A",IF(F9<=5,"B",IF(F9<=7,"C",IF(F9<=10,"D",IF(F9<=13,"E",IF(F9<=16,"F",IF(F9<=18,"G"))))))) | Q9: =C9 | S9: =G9 | V9: 14~20 | W9: =SUM(B9,D9,F9,H9,J9) | X9: +
A10: 8 | B10: 2 | C10: =VLOOKUP(B10,オッズデータ入力!C$7:D$25,2,FALSE) | F10: 2 | G10: =VLOOKUP(F10,オッズデータ入力!AA$7:AB$25,2,FALSE) | L10: =IF(B10<=2,"A",IF(B10<=5,"B",IF(B10<=7,"C",IF(B10<=10,"D",IF(B10<=13,"E",IF(B10<=16,"F",IF(B10<=18,"G"))))))) | N10: =IF(F10<=2,"A",IF(F10<=5,"B",IF(F10<=7,"C",IF(F10<=10,"D",IF(F10<=13,"E",IF(F10<=16,"F",IF(F10<=18,"G"))))))) | Q10: =C10 | S10: =G10 | V10: 14~20 | W10: =SUM(B10,D10,F10,H10,J10) | X10: +
A11: 9 | B11: 1 | C11: =VLOOKUP(B11,オッズデータ入力!C$7:D$25,2,FALSE) | H11: 1 | I11: =VLOOKUP(H11,オッズデータ入力!AM$7:AN$25,2,FALSE) | L11: =IF(B11<=2,"A",IF(B11<=5,"B",IF(B11<=7,"C",IF(B11<=10,"D",IF(B11<=13,"E",IF(B11<=16,"F",IF(B11<=18,"G"))))))) | O11: =IF(H11<=2,"A",IF(H11<=5,"B",IF(H11<=7,"C",IF(H11<=10,"D",IF(H11<=13,"E",IF(H11<=16,"F",IF(H11<=18,"G"))))))) | Q11: =C11 | T11: =I11 | V11: 14~20 | W11: =SUM(B11,D11,F11,H11,J11) | X11: +
A12: 10 | B12: 1 | C12: =VLOOKUP(B12,オッズデータ入力!C$7:D$25,2,FALSE) | H12: 2 | I12: =VLOOKUP(H12,オッズデータ入力!AM$7:AN$25,2,FALSE) | L12: =IF(B12<=2,"A",IF(B12<=5,"B",IF(B12<=7,"C",IF(B12<=10,"D",IF(B12<=13,"E",IF(B12<=16,"F",IF(B12<=18,"G"))))))) | O12: =IF(H12<=2,"A",IF(H12<=5,"B",IF(H12<=7,"C",IF(H12<=10,"D",IF(H12<=13,"E",IF(H12<=16,"F",IF(H12<=18,"G"))))))) | Q12: =C12 | T12: =I12 | V12: 14~20 | W12: =SUM(B12,D12,F12,H12,J12) | X12: +
A13: 11 | B13: 2 | C13: =VLOOKUP(B13,オッズデータ入力!C$7:D$25,2,FALSE) | H13: 1 | I13: =VLOOKUP(H13,オッズデータ入力!AM$7:AN$25,2,FALSE) | L13: =IF(B13<=2,"A",IF(B13<=5,"B",IF(B13<=7,"C",IF(B13<=10,"D",IF(B13<=13,"E",IF(B13<=16,"F",IF(B13<=18,"G"))))))) | O13: =IF(H13<=2,"A",IF(H13<=5,"B",IF(H13<=7,"C",IF(H13<=10,"D",IF(H13<=13,"E",IF(H13<=16,"F",IF(H13<=18,"G"))))))) | Q13: =C13 | T13: =I13 | V13: 14~20 | W13: =SUM(B13,D13,F13,H13,J13) | X13: +
A14: 12 | B14: 2 | C14: =VLOOKUP(B14,オッズデータ入力!C$7:D$25,2,FALSE) | H14: 2 | I14: =VLOOKUP(H14,オッズデータ入力!AM$7:AN$25,2,FALSE) | L14: =IF(B14<=2,"A",IF(B14<=5,"B",IF(B14<=7,"C",IF(B14<=10,"D",IF(B14<=13,"E",IF(B14<=16,"F",IF(B14<=18,"G"))))))) | O14: =IF(H14<=2,"A",IF(H14<=5,"B",IF(H14<=7,"C",IF(H14<=10,"D",IF(H14<=13,"E",IF(H14<=16,"F",IF(H14<=18,"G"))))))) | Q14: =C14 | T14: =I14 | V14: 14~20 | W14: =SUM(B14,D14,F14,H14,J14) | X14: +
A15: 13 | B15: 1 | C15: =VLOOKUP(B15,オッズデータ入力!C$7:D$25,2,FALSE) | J15: 1 | K15: =VLOOKUP(J15,オッズデータ入力!AY$7:AZ$25,2,FALSE) | L15: =IF(B15<=2,"A",IF(B15<=5,"B",IF(B15<=7,"C",IF(B15<=10,"D",IF(B15<=13,"E",IF(B15<=16,"F",IF(B15<=18,"G"))))))) | P15: =IF(J15<=2,"A",IF(J15<=5,"B",IF(J15<=7,"C",IF(J15<=10,"D",IF(J15<=13,"E",IF(J15<=16,"F",IF(J15<=18,"G"))))))) | Q15: =C15 | U15: =K15 | V15: 14~20 | W15: =SUM(B15,D15,F15,H15,J15) | X15: +
A16: 14 | B16: 1 | C16: =VLOOKUP(B16,オッズデータ入力!C$7:D$25,2,FALSE) | J16: 2 | K16: =VLOOKUP(J16,オッズデータ入力!AY$7:AZ$25,2,FALSE) | L16: =IF(B16<=2,"A",IF(B16<=5,"B",IF(B16<=7,"C",IF(B16<=10,"D",IF(B16<=13,"E",IF(B16<=16,"F",IF(B16<=18,"G"))))))) | P16: =IF(J16<=2,"A",IF(J16<=5,"B",IF(J16<=7,"C",IF(J16<=10,"D",IF(J16<=13,"E",IF(J16<=16,"F",IF(J16<=18,"G"))))))) | Q16: =C16 | U16: =K16 | V16: 14~20 | W16: =SUM(B16,D16,F16,H16,J16) | X16: +
A17: 15 | B17: 2 | C17: =VLOOKUP(B17,オッズデータ入力!C$7:D$25,2,FALSE) | J17: 1 | K17: =VLOOKUP(J17,オッズデータ入力!AY$7:AZ$25,2,FALSE) | L17: =IF(B17<=2,"A",IF(B17<=5,"B",IF(B17<=7,"C",IF(B17<=10,"D",IF(B17<=13,"E",IF(B17<=16,"F",IF(B17<=18,"G"))))))) | P17: =IF(J17<=2,"A",IF(J17<=5,"B",IF(J17<=7,"C",IF(J17<=10,"D",IF(J17<=13,"E",IF(J17<=16,"F",IF(J17<=18,"G"))))))) | Q17: =C17 | U17: =K17 | V17: 14~20 | W17: =SUM(B17,D17,F17,H17,J17) | X17: +
A18: 16 | B18: 2 | C18: =VLOOKUP(B18,オッズデータ入力!C$7:D$25,2,FALSE) | J18: 2 | K18: =VLOOKUP(J18,オッズデータ入力!AY$7:AZ$25,2,FALSE) | L18: =IF(B18<=2,"A",IF(B18<=5,"B",IF(B18<=7,"C",IF(B18<=10,"D",IF(B18<=13,"E",IF(B18<=16,"F",IF(B18<=18,"G"))))))) | P18: =IF(J18<=2,"A",IF(J18<=5,"B",IF(J18<=7,"C",IF(J18<=10,"D",IF(J18<=13,"E",IF(J18<=16,"F",IF(J18<=18,"G"))))))) | Q18: =C18 | U18: =K18 | V18: 14~20 | W18: =SUM(B18,D18,F18,H18,J18) | X18: +
A19: 17 | D19: 1 | E19: =VLOOKUP(D19,オッズデータ入力!O$7:P$25,2,FALSE) | F19: 1 | G19: =VLOOKUP(F19,オッズデータ入力!AA$7:AB$25,2,FALSE) | M19: =IF(D19<=2,"A",IF(D19<=5,"B",IF(D19<=7,"C",IF(D19<=10,"D",IF(D19<=13,"E",IF(D19<=16,"F",IF(D19<=18,"G"))))))) | N19: =IF(H19<=2,"A",IF(H19<=5,"B",IF(H19<=7,"C",IF(H19<=10,"D",IF(H19<=13,"E",IF(H19<=16,"F",IF(H19<=18,"G"))))))) | R19: =E19 | S19: =G19 | V19: 14~20 | W19: =SUM(B19,D19,F19,H19,J19) | X19: +
A20: 18 | D20: 1 | E20: =VLOOKUP(D20,オッズデータ入力!O$7:P$25,2,FALSE) | F20: 2 | G20: =VLOOKUP(F20,オッズデータ入力!AA$7:AB$25,2,FALSE) | M20: =IF(D20<=2,"A",IF(D20<=5,"B",IF(D20<=7,"C",IF(D20<=10,"D",IF(D20<=13,"E",IF(D20<=16,"F",IF(D20<=18,"G"))))))) | N20: =IF(H20<=2,"A",IF(H20<=5,"B",IF(H20<=7,"C",IF(H20<=10,"D",IF(H20<=13,"E",IF(H20<=16,"F",IF(H20<=18,"G"))))))) | R20: =E20 | S20: =G20 | V20: 14~20 | W20: =SUM(B20,D20,F20,H20,J20) | X20: +
A21: 19 | D21: 2 | E21: =VLOOKUP(D21,オッズデータ入力!O$7:P$25,2,FALSE) | F21: 1 | G21: =VLOOKUP(F21,オッズデータ入力!AA$7:AB$25,2,FALSE) | M21: =IF(D21<=2,"A",IF(D21<=5,"B",IF(D21<=7,"C",IF(D21<=10,"D",IF(D21<=13,"E",IF(D21<=16,"F",IF(D21<=18,"G"))))))) | N21: =IF(H21<=2,"A",IF(H21<=5,"B",IF(H21<=7,"C",IF(H21<=10,"D",IF(H21<=13,"E",IF(H21<=16,"F",IF(H21<=18,"G"))))))) | R21: =E21 | S21: =G21 | V21: 14~20 | W21: =SUM(B21,D21,F21,H21,J21) | X21: +
A22: 20 | D22: 2 | E22: =VLOOKUP(D22,オッズデータ入力!O$7:P$25,2,FALSE) | F22: 2 | G22: =VLOOKUP(F22,オッズデータ入力!AA$7:AB$25,2,FALSE) | M22: =IF(D22<=2,"A",IF(D22<=5,"B",IF(D22<=7,"C",IF(D22<=10,"D",IF(D22<=13,"E",IF(D22<=16,"F",IF(D22<=18,"G"))))))) | N22: =IF(H22<=2,"A",IF(H22<=5,"B",IF(H22<=7,"C",IF(H22<=10,"D",IF(H22<=13,"E",IF(H22<=16,"F",IF(H22<=18,"G"))))))) | R22: =E22 | S22: =G22 | V22: 14~20 | W22: =SUM(B22,D22,F22,H22,J22) | X22: +
A23: 21 | D23: 1 | E23: =VLOOKUP(D23,オッズデータ入力!O$7:P$25,2,FALSE) | H23: 1 | I23: =VLOOKUP(H23,オッズデータ入力!AM$7:AN$25,2,FALSE) | M23: =IF(D23<=2,"A",IF(D23<=5,"B",IF(D23<=7,"C",IF(D23<=10,"D",IF(D23<=13,"E",IF(D23<=16,"F",IF(D23<=18,"G"))))))) | O23: =IF(H23<=2,"A",IF(H23<=5,"B",IF(H23<=7,"C",IF(H23<=10,"D",IF(H23<=13,"E",IF(H23<=16,"F",IF(H23<=18,"G"))))))) | R23: =E23 | T23: =I23 | V23: 14~20 | W23: =SUM(B23,D23,F23,H23,J23) | X23: +
A24: 22 | D24: 1 | E24: =VLOOKUP(D24,オッズデータ入力!O$7:P$25,2,FALSE) | H24: 2 | I24: =VLOOKUP(H24,オッズデータ入力!AM$7:AN$25,2,FALSE) | M24: =IF(D24<=2,"A",IF(D24<=5,"B",IF(D24<=7,"C",IF(D24<=10,"D",IF(D24<=13,"E",IF(D24<=16,"F",IF(D24<=18,"G"))))))) | O24: =IF(H24<=2,"A",IF(H24<=5,"B",IF(H24<=7,"C",IF(H24<=10,"D",IF(H24<=13,"E",IF(H24<=16,"F",IF(H24<=18,"G"))))))) | R24: =E24 | T24: =I24 | V24: 14~20 | W24: =SUM(B24,D24,F24,H24,J24) | X24: +
A25: 23 | D25: 2 | E25: =VLOOKUP(D25,オッズデータ入力!O$7:P$25,2,FALSE) | H25: 1 | I25: =VLOOKUP(H25,オッズデータ入力!AM$7:AN$25,2,FALSE) | M25: =IF(D25<=2,"A",IF(D25<=5,"B",IF(D25<=7,"C",IF(D25<=10,"D",IF(D25<=13,"E",IF(D25<=16,"F",IF(D25<=18,"G"))))))) | O25: =IF(H25<=2,"A",IF(H25<=5,"B",IF(H25<=7,"C",IF(H25<=10,"D",IF(H25<=13,"E",IF(H25<=16,"F",IF(H25<=18,"G"))))))) | R25: =E25 | T25: =I25 | V25: 14~20 | W25: =SUM(B25,D25,F25,H25,J25) | X25: +
A26: 24 | D26: 2 | E26: =VLOOKUP(D26,オッズデータ入力!O$7:P$25,2,FALSE) | H26: 2 | I26: =VLOOKUP(H26,オッズデータ入力!AM$7:AN$25,2,FALSE) | M26: =IF(D26<=2,"A",IF(D26<=5,"B",IF(D26<=7,"C",IF(D26<=10,"D",IF(D26<=13,"E",IF(D26<=16,"F",IF(D26<=18,"G"))))))) | O26: =IF(H26<=2,"A",IF(H26<=5,"B",IF(H26<=7,"C",IF(H26<=10,"D",IF(H26<=13,"E",IF(H26<=16,"F",IF(H26<=18,"G"))))))) | R26: =E26 | T26: =I26 | V26: 14~20 | W26: =SUM(B26,D26,F26,H26,J26) | X26: +
A27: 25 | D27: 1 | E27: =VLOOKUP(D27,オッズデータ入力!O$7:P$25,2,FALSE) | J27: 1 | K27: =VLOOKUP(J27,オッズデータ入力!AY$7:AZ$25,2,FALSE) | M27: =IF(D27<=2,"A",IF(D27<=5,"B",IF(D27<=7,"C",IF(D27<=10,"D",IF(D27<=13,"E",IF(D27<=16,"F",IF(D27<=18,"G"))))))) | P27: =IF(J27<=2,"A",IF(J27<=5,"B",IF(J27<=7,"C",IF(J27<=10,"D",IF(J27<=13,"E",IF(J27<=16,"F",IF(J27<=18,"G"))))))) | R27: =E27 | U27: =K27 | V27: 14~20 | W27: =SUM(B27,D27,F27,H27,J27) | X27: +
A28: 26 | D28: 1 | E28: =VLOOKUP(D28,オッズデータ入力!O$7:P$25,2,FALSE) | J28: 2 | K28: =VLOOKUP(J28,オッズデータ入力!AY$7:AZ$25,2,FALSE) | M28: =IF(D28<=2,"A",IF(D28<=5,"B",IF(D28<=7,"C",IF(D28<=10,"D",IF(D28<=13,"E",IF(D28<=16,"F",IF(D28<=18,"G"))))))) | P28: =IF(J28<=2,"A",IF(J28<=5,"B",IF(J28<=7,"C",IF(J28<=10,"D",IF(J28<=13,"E",IF(J28<=16,"F",IF(J28<=18,"G"))))))) | R28: =E28 | U28: =K28 | V28: 14~20 | W28: =SUM(B28,D28,F28,H28,J28) | X28: +
A29: 27 | D29: 2 | E29: =VLOOKUP(D29,オッズデータ入力!O$7:P$25,2,FALSE) | J29: 1 | K29: =VLOOKUP(J29,オッズデータ入力!AY$7:AZ$25,2,FALSE) | M29: =IF(D29<=2,"A",IF(D29<=5,"B",IF(D29<=7,"C",IF(D29<=10,"D",IF(D29<=13,"E",IF(D29<=16,"F",IF(D29<=18,"G"))))))) | P29: =IF(J29<=2,"A",IF(J29<=5,"B",IF(J29<=7,"C",IF(J29<=10,"D",IF(J29<=13,"E",IF(J29<=16,"F",IF(J29<=18,"G"))))))) | R29: =E29 | U29: =K29 | V29: 14~20 | W29: =SUM(B29,D29,F29,H29,J29) | X29: +
A30: 28 | D30: 2 | E30: =VLOOKUP(D30,オッズデータ入力!O$7:P$25,2,FALSE) | J30: 2 | K30: =VLOOKUP(J30,オッズデータ入力!AY$7:AZ$25,2,FALSE) | M30: =IF(D30<=2,"A",IF(D30<=5,"B",IF(D30<=7,"C",IF(D30<=10,"D",IF(D30<=13,"E",IF(D30<=16,"F",IF(D30<=18,"G"))))))) | P30: =IF(J30<=2,"A",IF(J30<=5,"B",IF(J30<=7,"C",IF(J30<=10,"D",IF(J30<=13,"E",IF(J30<=16,"F",IF(J30<=18,"G"))))))) | R30: =E30 | U30: =K30 | V30: 14~20 | W30: =SUM(B30,D30,F30,H30,J30) | X30: +
A31: 29 | F31: 1 | G31: =VLOOKUP(F31,オッズデータ入力!AA$7:AB$25,2,FALSE) | H31: 1 | I31: =VLOOKUP(H31,オッズデータ入力!AM$7:AN$25,2,FALSE) | N31: =IF(H31<=2,"A",IF(H31<=5,"B",IF(H31<=7,"C",IF(H31<=10,"D",IF(H31<=13,"E",IF(H31<=16,"F",IF(H31<=18,"G"))))))) | O31: =IF(H31<=2,"A",IF(H31<=5,"B",IF(H31<=7,"C",IF(H31<=10,"D",IF(H31<=13,"E",IF(H31<=16,"F",IF(H31<=18,"G"))))))) | S31: =G31 | T31: =I31 | V31: 14~20 | W31: =SUM(B31,D31,F31,H31,J31) | X31: +
A32: 30 | F32: 1 | G32: =VLOOKUP(F32,オッズデータ入力!AA$7:AB$25,2,FALSE) | H32: 2 | I32: =VLOOKUP(H32,オッズデータ入力!AM$7:AN$25,2,FALSE) | N32: =IF(H32<=2,"A",IF(H32<=5,"B",IF(H32<=7,"C",IF(H32<=10,"D",IF(H32<=13,"E",IF(H32<=16,"F",IF(H32<=18,"G"))))))) | O32: =IF(H32<=2,"A",IF(H32<=5,"B",IF(H32<=7,"C",IF(H32<=10,"D",IF(H32<=13,"E",IF(H32<=16,"F",IF(H32<=18,"G"))))))) | S32: =G32 | T32: =I32 | V32: 14~20 | W32: =SUM(B32,D32,F32,H32,J32) | X32: +
A33: 31 | F33: 2 | G33: =VLOOKUP(F33,オッズデータ入力!AA$7:AB$25,2,FALSE) | H33: 1 | I33: =VLOOKUP(H33,オッズデータ入力!AM$7:AN$25,2,FALSE) | N33: =IF(H33<=2,"A",IF(H33<=5,"B",IF(H33<=7,"C",IF(H33<=10,"D",IF(H33<=13,"E",IF(H33<=16,"F",IF(H33<=18,"G"))))))) | O33: =IF(H33<=2,"A",IF(H33<=5,"B",IF(H33<=7,"C",IF(H33<=10,"D",IF(H33<=13,"E",IF(H33<=16,"F",IF(H33<=18,"G"))))))) | S33: =G33 | T33: =I33 | V33: 14~20 | W33: =SUM(B33,D33,F33,H33,J33) | X33: +
A34: 32 | F34: 2 | G34: =VLOOKUP(F34,オッズデータ入力!AA$7:AB$25,2,FALSE) | H34: 2 | I34: =VLOOKUP(H34,オッズデータ入力!AM$7:AN$25,2,FALSE) | N34: =IF(H34<=2,"A",IF(H34<=5,"B",IF(H34<=7,"C",IF(H34<=10,"D",IF(H34<=13,"E",IF(H34<=16,"F",IF(H34<=18,"G"))))))) | O34: =IF(H34<=2,"A",IF(H34<=5,"B",IF(H34<=7,"C",IF(H34<=10,"D",IF(H34<=13,"E",IF(H34<=16,"F",IF(H34<=18,"G"))))))) | S34: =G34 | T34: =I34 | V34: 14~20 | W34: =SUM(B34,D34,F34,H34,J34) | X34: +
A35: 33 | F35: 1 | G35: =VLOOKUP(F35,オッズデータ入力!AA$7:AB$25,2,FALSE) | J35: 1 | K35: =VLOOKUP(J35,オッズデータ入力!AY$7:AZ$25,2,FALSE) | N35: =IF(H35<=2,"A",IF(H35<=5,"B",IF(H35<=7,"C",IF(H35<=10,"D",IF(H35<=13,"E",IF(H35<=16,"F",IF(H35<=18,"G"))))))) | P35: =IF(J35<=2,"A",IF(J35<=5,"B",IF(J35<=7,"C",IF(J35<=10,"D",IF(J35<=13,"E",IF(J35<=16,"F",IF(J35<=18,"G"))))))) | S35: =G35 | U35: =K35 | V35: 14~20 | W35: =SUM(B35,D35,F35,H35,J35) | X35: +
A36: 34 | F36: 1 | G36: =VLOOKUP(F36,オッズデータ入力!AA$7:AB$25,2,FALSE) | J36: 2 | K36: =VLOOKUP(J36,オッズデータ入力!AY$7:AZ$25,2,FALSE) | N36: =IF(H36<=2,"A",IF(H36<=5,"B",IF(H36<=7,"C",IF(H36<=10,"D",IF(H36<=13,"E",IF(H36<=16,"F",IF(H36<=18,"G"))))))) | P36: =IF(J36<=2,"A",IF(J36<=5,"B",IF(J36<=7,"C",IF(J36<=10,"D",IF(J36<=13,"E",IF(J36<=16,"F",IF(J36<=18,"G"))))))) | S36: =G36 | U36: =K36 | V36: 14~20 | W36: =SUM(B36,D36,F36,H36,J36) | X36: +
A37: 35 | F37: 2 | G37: =VLOOKUP(F37,オッズデータ入力!AA$7:AB$25,2,FALSE) | J37: 1 | K37: =VLOOKUP(J37,オッズデータ入力!AY$7:AZ$25,2,FALSE) | N37: =IF(H37<=2,"A",IF(H37<=5,"B",IF(H37<=7,"C",IF(H37<=10,"D",IF(H37<=13,"E",IF(H37<=16,"F",IF(H37<=18,"G"))))))) | P37: =IF(J37<=2,"A",IF(J37<=5,"B",IF(J37<=7,"C",IF(J37<=10,"D",IF(J37<=13,"E",IF(J37<=16,"F",IF(J37<=18,"G"))))))) | S37: =G37 | U37: =K37 | V37: 14~20 | W37: =SUM(B37,D37,F37,H37,J37) | X37: +
A38: 36 | F38: 2 | G38: =VLOOKUP(F38,オッズデータ入力!AA$7:AB$25,2,FALSE) | J38: 2 | K38: =VLOOKUP(J38,オッズデータ入力!AY$7:AZ$25,2,FALSE) | N38: =IF(H38<=2,"A",IF(H38<=5,"B",IF(H38<=7,"C",IF(H38<=10,"D",IF(H38<=13,"E",IF(H38<=16,"F",IF(H38<=18,"G"))))))) | P38: =IF(J38<=2,"A",IF(J38<=5,"B",IF(J38<=7,"C",IF(J38<=10,"D",IF(J38<=13,"E",IF(J38<=16,"F",IF(J38<=18,"G"))))))) | S38: =G38 | U38: =K38 | V38: 14~20 | W38: =SUM(B38,D38,F38,H38,J38) | X38: +
A39: 37 | H39: 1 | I39: =VLOOKUP(H39,オッズデータ入力!AM$7:AN$25,2,FALSE) | J39: 1 | K39: =VLOOKUP(J39,オッズデータ入力!AY$7:AZ$25,2,FALSE) | O39: =IF(H39<=2,"A",IF(H39<=5,"B",IF(H39<=7,"C",IF(H39<=10,"D",IF(H39<=13,"E",IF(H39<=16,"F",IF(H39<=18,"G"))))))) | P39: =IF(J39<=2,"A",IF(J39<=5,"B",IF(J39<=7,"C",IF(J39<=10,"D",IF(J39<=13,"E",IF(J39<=16,"F",IF(J39<=18,"G"))))))) | T39: =I39 | U39: =K39 | V39: 14~20 | W39: =SUM(B39,D39,F39,H39,J39) | X39: +
A40: 38 | H40: 1 | I40: =VLOOKUP(H40,オッズデータ入力!AM$7:AN$25,2,FALSE) | J40: 2 | K40: =VLOOKUP(J40,オッズデータ入力!AY$7:AZ$25,2,FALSE) | O40: =IF(H40<=2,"A",IF(H40<=5,"B",IF(H40<=7,"C",IF(H40<=10,"D",IF(H40<=13,"E",IF(H40<=16,"F",IF(H40<=18,"G"))))))) | P40: =IF(J40<=2,"A",IF(J40<=5,"B",IF(J40<=7,"C",IF(J40<=10,"D",IF(J40<=13,"E",IF(J40<=16,"F",IF(J40<=18,"G"))))))) | T40: =I40 | U40: =K40 | V40: 14~20 | W40: =SUM(B40,D40,F40,H40,J40) | X40: +
A41: 39 | H41: 2 | I41: =VLOOKUP(H41,オッズデータ入力!AM$7:AN$25,2,FALSE) | J41: 1 | K41: =VLOOKUP(J41,オッズデータ入力!AY$7:AZ$25,2,FALSE) | O41: =IF(H41<=2,"A",IF(H41<=5,"B",IF(H41<=7,"C",IF(H41<=10,"D",IF(H41<=13,"E",IF(H41<=16,"F",IF(H41<=18,"G"))))))) | P41: =IF(J41<=2,"A",IF(J41<=5,"B",IF(J41<=7,"C",IF(J41<=10,"D",IF(J41<=13,"E",IF(J41<=16,"F",IF(J41<=18,"G"))))))) | T41: =I41 | U41: =K41 | V41: 14~20 | W41: =SUM(B41,D41,F41,H41,J41) | X41: +
...

Sheet 3回
B2: WIN1 | D2: WIN2 | F2: WIN3 | H2: WIN4 | J2: WIN5 | L2: WIN1 | M2: WIN2 | N2: WIN3 | O2: WIN4 | P2: WIN5 | Q2: WIN1 | R2: WIN2 | S2: WIN3 | T2: WIN4 | U2: WIN5 | V2: 人気の和 | W2: 人気の和
A3: 1 | B3: 1 | C3: =VLOOKUP(B3,オッズデータ入力!C$7:D$25,2,FALSE) | D3: 1 | E3: =VLOOKUP(D3,オッズデータ入力!O$7:P$25,2,FALSE) | F3: 1 | G3: =VLOOKUP(F3,オッズデータ入力!AA$7:AB$25,2,FALSE) | L3: =IF(B3<=2,"A",IF(B3<=5,"B",IF(B3<=7,"C",IF(B3<=10,"D",IF(B3<=13,"E",IF(B3<=16,"F",IF(B3<=18,"G"))))))) | M3: =IF(D3<=2,"A",IF(D3<=5,"B",IF(D3<=7,"C",IF(D3<=10,"D",IF(D3<=13,"E",IF(D3<=16,"F",IF(D3<=18,"G"))))))) | N3: =IF(F3<=2,"A",IF(F3<=5,"B",IF(F3<=7,"C",IF(F3<=10,"D",IF(F3<=13,"E",IF(F3<=16,"F",IF(F3<=18,"G"))))))) | Q3: =C3 | R3: =E3 | S3: =G3 | V3: 14~20 | W3: =SUM(B3,D3,F3,H3,J3) | X3: +
A4: 2 | B4: 1 | C4: =VLOOKUP(B4,オッズデータ入力!C$7:D$25,2,FALSE) | D4: 1 | E4: =VLOOKUP(D4,オッズデータ入力!O$7:P$25,2,FALSE) | F4: 2 | G4: =VLOOKUP(F4,オッズデータ入力!AA$7:AB$25,2,FALSE) | L4: =IF(B4<=2,"A",IF(B4<=5,"B",IF(B4<=7,"C",IF(B4<=10,"D",IF(B4<=13,"E",IF(B4<=16,"F",IF(B4<=18,"G"))))))) | M4: =IF(D4<=2,"A",IF(D4<=5,"B",IF(D4<=7,"C",IF(D4<=10,"D",IF(D4<=13,"E",IF(D4<=16,"F",IF(D4<=18,"G"))))))) | N4: =IF(F4<=2,"A",IF(F4<=5,"B",IF(F4<=7,"C",IF(F4<=10,"D",IF(F4<=13,"E",IF(F4<=16,"F",IF(F4<=18,"G"))))))) | Q4: =C4 | R4: =E4 | S4: =G4 | V4: 14~20 | W4: =SUM(B4,D4,F4,H4,J4) | X4: +
A5: 3 | B5: 1 | C5: =VLOOKUP(B5,オッズデータ入力!C$7:D$25,2,FALSE) | D5: 2 | E5: =VLOOKUP(D5,オッズデータ入力!O$7:P$25,2,FALSE) | F5: 1 | G5: =VLOOKUP(F5,オッズデータ入力!AA$7:AB$25,2,FALSE) | L5: =IF(B5<=2,"A",IF(B5<=5,"B",IF(B5<=7,"C",IF(B5<=10,"D",IF(B5<=13,"E",IF(B5<=16,"F",IF(B5<=18,"G"))))))) | M5: =IF(D5<=2,"A",IF(D5<=5,"B",IF(D5<=7,"C",IF(D5<=10,"D",IF(D5<=13,"E",IF(D5<=16,"F",IF(D5<=18,"G"))))))) | N5: =IF(F5<=2,"A",IF(F5<=5,"B",IF(F5<=7,"C",IF(F5<=10,"D",IF(F5<=13,"E",IF(F5<=16,"F",IF(F5<=18,"G"))))))) | Q5: =C5 | R5: =E5 | S5: =G5 | V5: 14~20 | W5: =SUM(B5,D5,F5,H5,J5) | X5: +
A6: 4 | B6: 1 | C6: =VLOOKUP(B6,オッズデータ入力!C$7:D$25,2,FALSE) | D6: 2 | E6: =VLOOKUP(D6,オッズデータ入力!O$7:P$25,2,FALSE) | F6: 2 | G6: =VLOOKUP(F6,オッズデータ入力!AA$7:AB$25,2,FALSE) | L6: =IF(B6<=2,"A",IF(B6<=5,"B",IF(B6<=7,"C",IF(B6<=10,"D",IF(B6<=13,"E",IF(B6<=16,"F",IF(B6<=18,"G"))))))) | M6: =IF(D6<=2,"A",IF(D6<=5,"B",IF(D6<=7,"C",IF(D6<=10,"D",IF(D6<=13,"E",IF(D6<=16,"F",IF(D6<=18,"G"))))))) | N6: =IF(F6<=2,"A",IF(F6<=5,"B",IF(F6<=7,"C",IF(F6<=10,"D",IF(F6<=13,"E",IF(F6<=16,"F",IF(F6<=18,"G"))))))) | Q6: =C6 | R6: =E6 | S6: =G6 | V6: 14~20 | W6: =SUM(B6,D6,F6,H6,J6) | X6: +
A7: 5 | B7: 2 | C7: =VLOOKUP(B7,オッズデータ入力!C$7:D$25,2,FALSE) | D7: 1 | E7: =VLOOKUP(D7,オッズデータ入力!O$7:P$25,2,FALSE) | F7: 1 | G7: =VLOOKUP(F7,オッズデータ入力!AA$7:AB$25,2,FALSE) | L7: =IF(B7<=2,"A",IF(B7<=5,"B",IF(B7<=7,"C",IF(B7<=10,"D",IF(B7<=13,"E",IF(B7<=16,"F",IF(B7<=18,"G"))))))) | M7: =IF(D7<=2,"A",IF(D7<=5,"B",IF(D7<=7,"C",IF(D7<=10,"D",IF(D7<=13,"E",IF(D7<=16,"F",IF(D7<=18,"G"))))))) | N7: =IF(F7<=2,"A",IF(F7<=5,"B",IF(F7<=7,"C",IF(F7<=10,"D",IF(F7<=13,"E",IF(F7<=16,"F",IF(F7<=18,"G"))))))) | Q7: =C7 | R7: =E7 | S7: =G7 | V7: 14~20 | W7: =SUM(B7,D7,F7,H7,J7) | X7: +
A8: 6 | B8: 2 | C8: =VLOOKUP(B8,オッズデータ入力!C$7:D$25,2,FALSE) | D8: 1 | E8: =VLOOKUP(D8,オッズデータ入力!O$7:P$25,2,FALSE) | F8: 2 | G8: =VLOOKUP(F8,オッズデータ入力!AA$7:AB$25,2,FALSE) | L8: =IF(B8<=2,"A",IF(B8<=5,"B",IF(B8<=7,"C",IF(B8<=10,"D",IF(B8<=13,"E",IF(B8<=16,"F",IF(B8<=18,"G"))))))) | M8: =IF(D8<=2,"A",IF(D8<=5,"B",IF(D8<=7,"C",IF(D8<=10,"D",IF(D8<=13,"E",IF(D8<=16,"F",IF(D8<=18,"G"))))))) | N8: =IF(F8<=2,"A",IF(F8<=5,"B",IF(F8<=7,"C",IF(F8<=10,"D",IF(F8<=13,"E",IF(F8<=16,"F",IF(F8<=18,"G"))))))) | Q8: =C8 | R8: =E8 | S8: =G8 | V8: 14~20 | W8: =SUM(B8,D8,F8,H8,J8) | X8: +
A9: 7 | B9: 2 | C9: =VLOOKUP(B9,オッズデータ入力!C$7:D$25,2,FALSE) | D9: 2 | E9: =VLOOKUP(D9,オッズデータ入力!O$7:P$25,2,FALSE) | F9: 1 | G9: =VLOOKUP(F9,オッズデータ入力!AA$7:AB$25,2,FALSE) | L9: =IF(B9<=2,"A",IF(B9<=5,"B",IF(B9<=7,"C",IF(B9<=10,"D",IF(B9<=13,"E",IF(B9<=16,"F",IF(B9<=18,"G"))))))) | M9: =IF(D9<=2,"A",IF(D9<=5,"B",IF(D9<=7,"C",IF(D9<=10,"D",IF(D9<=13,"E",IF(D9<=16,"F",IF(D9<=18,"G"))))))) | N9: =IF(F9<=2,"A",IF(F9<=5,"B",IF(F9<=7,"C",IF(F9<=10,"D",IF(F9<=13,"E",IF(F9<=16,"F",IF(F9<=18,"G"))))))) | Q9: =C9 | R9: =E9 | S9: =G9 | V9: 14~20 | W9: =SUM(B9,D9,F9,H9,J9) | X9: +
A10: 8 | B10: 2 | C10: =VLOOKUP(B10,オッズデータ入力!C$7:D$25,2,FALSE) | D10: 2 | E10: =VLOOKUP(D10,オッズデータ入力!O$7:P$25,2,FALSE) | F10: 2 | G10: =VLOOKUP(F10,オッズデータ入力!AA$7:AB$25,2,FALSE) | L10: =IF(B10<=2,"A",IF(B10<=5,"B",IF(B10<=7,"C",IF(B10<=10,"D",IF(B10<=13,"E",IF(B10<=16,"F",IF(B10<=18,"G"))))))) | M10: =IF(D10<=2,"A",IF(D10<=5,"B",IF(D10<=7,"C",IF(D10<=10,"D",IF(D10<=13,"E",IF(D10<=16,"F",IF(D10<=18,"G"))))))) | N10: =IF(F10<=2,"A",IF(F10<=5,"B",IF(F10<=7,"C",IF(F10<=10,"D",IF(F10<=13,"E",IF(F10<=16,"F",IF(F10<=18,"G"))))))) | Q10: =C10 | R10: =E10 | S10: =G10 | V10: 14~20 | W10: =SUM(B10,D10,F10,H10,J10) | X10: +
A11: 9 | B11: 1 | C11: =VLOOKUP(B11,オッズデータ入力!C$7:D$25,2,FALSE) | D11: 1 | E11: =VLOOKUP(D11,オッズデータ入力!O$7:P$25,2,FALSE) | H11: 1 | I11: =VLOOKUP(H11,オッズデータ入力!AM$7:AN$25,2,FALSE) | L11: =IF(B11<=2,"A",IF(B11<=5,"B",IF(B11<=7,"C",IF(B11<=10,"D",IF(B11<=13,"E",IF(B11<=16,"F",IF(B11<=18,"G"))))))) | M11: =IF(D11<=2,"A",IF(D11<=5,"B",IF(D11<=7,"C",IF(D11<=10,"D",IF(D11<=13,"E",IF(D11<=16,"F",IF(D11<=18,"G"))))))) | O11: =IF(H11<=2,"A",IF(H11<=5,"B",IF(H11<=7,"C",IF(H11<=10,"D",IF(H11<=13,"E",IF(H11<=16,"F",IF(H11<=18,"G"))))))) | Q11: =C11 | R11: =E11 | T11: =I11 | V11: 14~20 | W11: =SUM(B11,D11,F11,H11,J11) | X11: +
A12: 10 | B12: 1 | C12: =VLOOKUP(B12,オッズデータ入力!C$7:D$25,2,FALSE) | D12: 1 | E12: =VLOOKUP(D12,オッズデータ入力!O$7:P$25,2,FALSE) | H12: 2 | I12: =VLOOKUP(H12,オッズデータ入力!AM$7:AN$25,2,FALSE) | L12: =IF(B12<=2,"A",IF(B12<=5,"B",IF(B12<=7,"C",IF(B12<=10,"D",IF(B12<=13,"E",IF(B12<=16,"F",IF(B12<=18,"G"))))))) | M12: =IF(D12<=2,"A",IF(D12<=5,"B",IF(D12<=7,"C",IF(D12<=10,"D",IF(D12<=13,"E",IF(D12<=16,"F",IF(D12<=18,"G"))))))) | O12: =IF(H12<=2,"A",IF(H12<=5,"B",IF(H12<=7,"C",IF(H12<=10,"D",IF(H12<=13,"E",IF(H12<=16,"F",IF(H12<=18,"G"))))))) | Q12: =C12 | R12: =E12 | T12: =I12 | V12: 14~20 | W12: =SUM(B12,D12,F12,H12,J12) | X12: +
A13: 11 | B13: 1 | C13: =VLOOKUP(B13,オッズデータ入力!C$7:D$25,2,FALSE) | D13: 2 | E13: =VLOOKUP(D13,オッズデータ入力!O$7:P$25,2,FALSE) | H13: 1 | I13: =VLOOKUP(H13,オッズデータ入力!AM$7:AN$25,2,FALSE) | L13: =IF(B13<=2,"A",IF(B13<=5,"B",IF(B13<=7,"C",IF(B13<=10,"D",IF(B13<=13,"E",IF(B13<=16,"F",IF(B13<=18,"G"))))))) | M13: =IF(D13<=2,"A",IF(D13<=5,"B",IF(D13<=7,"C",IF(D13<=10,"D",IF(D13<=13,"E",IF(D13<=16,"F",IF(D13<=18,"G"))))))) | O13: =IF(H13<=2,"A",IF(H13<=5,"B",IF(H13<=7,"C",IF(H13<=10,"D",IF(H13<=13,"E",IF(H13<=16,"F",IF(H13<=18,"G"))))))) | Q13: =C13 | R13: =E13 | T13: =I13 | V13: 14~20 | W13: =SUM(B13,D13,F13,H13,J13) | X13: +
A14: 12 | B14: 1 | C14: =VLOOKUP(B14,オッズデータ入力!C$7:D$25,2,FALSE) | D14: 2 | E14: =VLOOKUP(D14,オッズデータ入力!O$7:P$25,2,FALSE) | H14: 2 | I14: =VLOOKUP(H14,オッズデータ入力!AM$7:AN$25,2,FALSE) | L14: =IF(B14<=2,"A",IF(B14<=5,"B",IF(B14<=7,"C",IF(B14<=10,"D",IF(B14<=13,"E",IF(B14<=16,"F",IF(B14<=18,"G"))))))) | M14: =IF(D14<=2,"A",IF(D14<=5,"B",IF(D14<=7,"C",IF(D14<=10,"D",IF(D14<=13,"E",IF(D14<=16,"F",IF(D14<=18,"G"))))))) | O14: =IF(H14<=2,"A",IF(H14<=5,"B",IF(H14<=7,"C",IF(H14<=10,"D",IF(H14<=13,"E",IF(H14<=16,"F",IF(H14<=18,"G"))))))) | Q14: =C14 | R14: =E14 | T14: =I14 | V14: 14~20 | W14: =SUM(B14,D14,F14,H14,J14) | X14: +
A15: 13 | B15: 2 | C15: =VLOOKUP(B15,オッズデータ入力!C$7:D$25,2,FALSE) | D15: 1 | E15: =VLOOKUP(D15,オッズデータ入力!O$7:P$25,2,FALSE) | H15: 1 | I15: =VLOOKUP(H15,オッズデータ入力!AM$7:AN$25,2,FALSE) | L15: =IF(B15<=2,"A",IF(B15<=5,"B",IF(B15<=7,"C",IF(B15<=10,"D",IF(B15<=13,"E",IF(B15<=16,"F",IF(B15<=18,"G"))))))) | M15: =IF(D15<=2,"A",IF(D15<=5,"B",IF(D15<=7,"C",IF(D15<=10,"D",IF(D15<=13,"E",IF(D15<=16,"F",IF(D15<=18,"G"))))))) | O15: =IF(H15<=2,"A",IF(H15<=5,"B",IF(H15<=7,"C",IF(H15<=10,"D",IF(H15<=13,"E",IF(H15<=16,"F",IF(H15<=18,"G"))))))) | Q15: =C15 | R15: =E15 | T15: =I15 | V15: 14~20 | W15: =SUM(B15,D15,F15,H15,J15) | X15: +
A16: 14 | B16: 2 | C16: =VLOOKUP(B16,オッズデータ入力!C$7:D$25,2,FALSE) | D16: 1 | E16: =VLOOKUP(D16,オッズデータ入力!O$7:P$25,2,FALSE) | H16: 2 | I16: =VLOOKUP(H16,オッズデータ入力!AM$7:AN$25,2,FALSE) | L16: =IF(B16<=2,"A",IF(B16<=5,"B",IF(B16<=7,"C",IF(B16<=10,"D",IF(B16<=13,"E",IF(B16<=16,"F",IF(B16<=18,"G"))))))) | M16: =IF(D16<=2,"A",IF(D16<=5,"B",IF(D16<=7,"C",IF(D16<=10,"D",IF(D16<=13,"E",IF(D16<=16,"F",IF(D16<=18,"G"))))))) | O16: =IF(H16<=2,"A",IF(H16<=5,"B",IF(H16<=7,"C",IF(H16<=10,"D",IF(H16<=13,"E",IF(H16<=16,"F",IF(H16<=18,"G"))))))) | Q16: =C16 | R16: =E16 | T16: =I16 | V16: 14~20 | W16: =SUM(B16,D16,F16,H16,J16) | X16: +
A17: 15 | B17: 2 | C17: =VLOOKUP(B17,オッズデータ入力!C$7:D$25,2,FALSE) | D17: 2 | E17: =VLOOKUP(D17,オッズデータ入力!O$7:P$25,2,FALSE) | H17: 1 | I17: =VLOOKUP(H17,オッズデータ入力!AM$7:AN$25,2,FALSE) | L17: =IF(B17<=2,"A",IF(B17<=5,"B",IF(B17<=7,"C",IF(B17<=10,"D",IF(B17<=13,"E",IF(B17<=16,"F",IF(B17<=18,"G"))))))) | M17: =IF(D17<=2,"A",IF(D17<=5,"B",IF(D17<=7,"C",IF(D17<=10,"D",IF(D17<=13,"E",IF(D17<=16,"F",IF(D17<=18,"G"))))))) | O17: =IF(H17<=2,"A",IF(H17<=5,"B",IF(H17<=7,"C",IF(H17<=10,"D",IF(H17<=13,"E",IF(H17<=16,"F",IF(H17<=18,"G"))))))) | Q17: =C17 | R17: =E17 | T17: =I17 | V17: 14~20 | W17: =SUM(B17,D17,F17,H17,J17) | X17: +
A18: 16 | B18: 2 | C18: =VLOOKUP(B18,オッズデータ入力!C$7:D$25,2,FALSE) | D18: 2 | E18: =VLOOKUP(D18,オッズデータ入力!O$7:P$25,2,FALSE) | H18: 2 | I18: =VLOOKUP(H18,オッズデータ入力!AM$7:AN$25,2,FALSE) | L18: =IF(B18<=2,"A",IF(B18<=5,"B",IF(B18<=7,"C",IF(B18<=10,"D",IF(B18<=13,"E",IF(B18<=16,"F",IF(B18<=18,"G"))))))) | M18: =IF(D18<=2,"A",IF(D18<=5,"B",IF(D18<=7,"C",IF(D18<=10,"D",IF(D18<=13,"E",IF(D18<=16,"F",IF(D18<=18,"G"))))))) | O18: =IF(H18<=2,"A",IF(H18<=5,"B",IF(H18<=7,"C",IF(H18<=10,"D",IF(H18<=13,"E",IF(H18<=16,"F",IF(H18<=18,"G"))))))) | Q18: =C18 | R18: =E18 | T18: =I18 | V18: 14~20 | W18: =SUM(B18,D18,F18,H18,J18) | X18: +
A19: 17 | B19: 1 | C19: =VLOOKUP(B19,オッズデータ入力!C$7:D$25,2,FALSE) | D19: 1 | E19: =VLOOKUP(D19,オッズデータ入力!O$7:P$25,2,FALSE) | J19: 1 | K19: =VLOOKUP(J19,オッズデータ入力!AY$7:AZ$25,2,FALSE) | L19: =IF(B19<=2,"A",IF(B19<=5,"B",IF(B19<=7,"C",IF(B19<=10,"D",IF(B19<=13,"E",IF(B19<=16,"F",IF(B19<=18,"G"))))))) | M19: =IF(D19<=2,"A",IF(D19<=5,"B",IF(D19<=7,"C",IF(D19<=10,"D",IF(D19<=13,"E",IF(D19<=16,"F",IF(D19<=18,"G"))))))) | P19: =IF(J19<=2,"A",IF(J19<=5,"B",IF(J19<=7,"C",IF(J19<=10,"D",IF(J19<=13,"E",IF(J19<=16,"F",IF(J19<=18,"G"))))))) | Q19: =C19 | R19: =E19 | U19: =K19 | V19: 14~20 | W19: =SUM(B19,D19,F19,H19,J19) | X19: +
A20: 18 | B20: 1 | C20: =VLOOKUP(B20,オッズデータ入力!C$7:D$25,2,FALSE) | D20: 1 | E20: =VLOOKUP(D20,オッズデータ入力!O$7:P$25,2,FALSE) | J20: 2 | K20: =VLOOKUP(J20,オッズデータ入力!AY$7:AZ$25,2,FALSE) | L20: =IF(B20<=2,"A",IF(B20<=5,"B",IF(B20<=7,"C",IF(B20<=10,"D",IF(B20<=13,"E",IF(B20<=16,"F",IF(B20<=18,"G"))))))) | M20: =IF(D20<=2,"A",IF(D20<=5,"B",IF(D20<=7,"C",IF(D20<=10,"D",IF(D20<=13,"E",IF(D20<=16,"F",IF(D20<=18,"G"))))))) | P20: =IF(J20<=2,"A",IF(J20<=5,"B",IF(J20<=7,"C",IF(J20<=10,"D",IF(J20<=13,"E",IF(J20<=16,"F",IF(J20<=18,"G"))))))) | Q20: =C20 | R20: =E20 | U20: =K20 | V20: 14~20 | W20: =SUM(B20,D20,F20,H20,J20) | X20: +
A21: 19 | B21: 1 | C21: =VLOOKUP(B21,オッズデータ入力!C$7:D$25,2,FALSE) | D21: 2 | E21: =VLOOKUP(D21,オッズデータ入力!O$7:P$25,2,FALSE) | J21: 1 | K21: =VLOOKUP(J21,オッズデータ入力!AY$7:AZ$25,2,FALSE) | L21: =IF(B21<=2,"A",IF(B21<=5,"B",IF(B21<=7,"C",IF(B21<=10,"D",IF(B21<=13,"E",IF(B21<=16,"F",IF(B21<=18,"G"))))))) | M21: =IF(D21<=2,"A",IF(D21<=5,"B",IF(D21<=7,"C",IF(D21<=10,"D",IF(D21<=13,"E",IF(D21<=16,"F",IF(D21<=18,"G"))))))) | P21: =IF(J21<=2,"A",IF(J21<=5,"B",IF(J21<=7,"C",IF(J21<=10,"D",IF(J21<=13,"E",IF(J21<=16,"F",IF(J21<=18,"G"))))))) | Q21: =C21 | R21: =E21 | U21: =K21 | V21: 14~20 | W21: =SUM(B21,D21,F21,H21,J21) | X21: +
A22: 20 | B22: 1 | C22: =VLOOKUP(B22,オッズデータ入力!C$7:D$25,2,FALSE) | D22: 2 | E22: =VLOOKUP(D22,オッズデータ入力!O$7:P$25,2,FALSE) | J22: 2 | K22: =VLOOKUP(J22,オッズデータ入力!AY$7:AZ$25,2,FALSE) | L22: =IF(B22<=2,"A",IF(B22<=5,"B",IF(B22<=7,"C",IF(B22<=10,"D",IF(B22<=13,"E",IF(B22<=16,"F",IF(B22<=18,"G"))))))) | M22: =IF(D22<=2,"A",IF(D22<=5,"B",IF(D22<=7,"C",IF(D22<=10,"D",IF(D22<=13,"E",IF(D22<=16,"F",IF(D22<=18,"G"))))))) | P22: =IF(J22<=2,"A",IF(J22<=5,"B",IF(J22<=7,"C",IF(J22<=10,"D",IF(J22<=13,"E",IF(J22<=16,"F",IF(J22<=18,"G"))))))) | Q22: =C22 | R22: =E22 | U22: =K22 | V22: 14~20 | W22: =SUM(B22,D22,F22,H22,J22) | X22: +
A23: 21 | B23: 2 | C23: =VLOOKUP(B23,オッズデータ入力!C$7:D$25,2,FALSE) | D23: 1 | E23: =VLOOKUP(D23,オッズデータ入力!O$7:P$25,2,FALSE) | J23: 1 | K23: =VLOOKUP(J23,オッズデータ入力!AY$7:AZ$25,2,FALSE) | L23: =IF(B23<=2,"A",IF(B23<=5,"B",IF(B23<=7,"C",IF(B23<=10,"D",IF(B23<=13,"E",IF(B23<=16,"F",IF(B23<=18,"G"))))))) | M23: =IF(D23<=2,"A",IF(D23<=5,"B",IF(D23<=7,"C",IF(D23<=10,"D",IF(D23<=13,"E",IF(D23<=16,"F",IF(D23<=18,"G"))))))) | P23: =IF(J23<=2,"A",IF(J23<=5,"B",IF(J23<=7,"C",IF(J23<=10,"D",IF(J23<=13,"E",IF(J23<=16,"F",IF(J23<=18,"G"))))))) | Q23: =C23 | R23: =E23 | U23: =K23 | V23: 14~20 | W23: =SUM(B23,D23,F23,H23,J23) | X23: +
A24: 22 | B24: 2 | C24: =VLOOKUP(B24,オッズデータ入力!C$7:D$25,2,FALSE) | D24: 1 | E24: =VLOOKUP(D24,オッズデータ入力!O$7:P$25,2,FALSE) | J24: 2 | K24: =VLOOKUP(J24,オッズデータ入力!AY$7:AZ$25,2,FALSE) | L24: =IF(B24<=2,"A",IF(B24<=5,"B",IF(B24<=7,"C",IF(B24<=10,"D",IF(B24<=13,"E",IF(B24<=16,"F",IF(B24<=18,"G"))))))) | M24: =IF(D24<=2,"A",IF(D24<=5,"B",IF(D24<=7,"C",IF(D24<=10,"D",IF(D24<=13,"E",IF(D24<=16,"F",IF(D24<=18,"G"))))))) | P24: =IF(J24<=2,"A",IF(J24<=5,"B",IF(J24<=7,"C",IF(J24<=10,"D",IF(J24<=13,"E",IF(J24<=16,"F",IF(J24<=18,"G"))))))) | Q24: =C24 | R24: =E24 | U24: =K24 | V24: 14~20 | W24: =SUM(B24,D24,F24,H24,J24) | X24: +
A25: 23 | B25: 2 | C25: =VLOOKUP(B25,オッズデータ入力!C$7:D$25,2,FALSE) | D25: 2 | E25: =VLOOKUP(D25,オッズデータ入力!O$7:P$25,2,FALSE) | J25: 1 | K25: =VLOOKUP(J25,オッズデータ入力!AY$7:AZ$25,2,FALSE) | L25: =IF(B25<=2,"A",IF(B25<=5,"B",IF(B25<=7,"C",IF(B25<=10,"D",IF(B25<=13,"E",IF(B25<=16,"F",IF(B25<=18,"G"))))))) | M25: =IF(D25<=2,"A",IF(D25<=5,"B",IF(D25<=7,"C",IF(D25<=10,"D",IF(D25<=13,"E",IF(D25<=16,"F",IF(D25<=18,"G"))))))) | P25: =IF(J25<=2,"A",IF(J25<=5,"B",IF(J25<=7,"C",IF(J25<=10,"D",IF(J25<=13,"E",IF(J25<=16,"F",IF(J25<=18,"G"))))))) | Q25: =C25 | R25: =E25 | U25: =K25 | V25: 14~20 | W25: =SUM(B25,D25,F25,H25,J25) | X25: +
A26: 24 | B26: 2 | C26: =VLOOKUP(B26,オッズデータ入力!C$7:D$25,2,FALSE) | D26: 2 | E26: =VLOOKUP(D26,オッズデータ入力!O$7:P$25,2,FALSE) | J26: 2 | K26: =VLOOKUP(J26,オッズデータ入力!AY$7:AZ$25,2,FALSE) | L26: =IF(B26<=2,"A",IF(B26<=5,"B",IF(B26<=7,"C",IF(B26<=10,"D",IF(B26<=13,"E",IF(B26<=16,"F",IF(B26<=18,"G"))))))) | M26: =IF(D26<=2,"A",IF(D26<=5,"B",IF(D26<=7,"C",IF(D26<=10,"D",IF(D26<=13,"E",IF(D26<=16,"F",IF(D26<=18,"G"))))))) | P26: =IF(J26<=2,"A",IF(J26<=5,"B",IF(J26<=7,"C",IF(J26<=10,"D",IF(J26<=13,"E",IF(J26<=16,"F",IF(J26<=18,"G"))))))) | Q26: =C26 | R26: =E26 | U26: =K26 | V26: 14~20 | W26: =SUM(B26,D26,F26,H26,J26) | X26: +
A27: 25 | B27: 1 | C27: =VLOOKUP(B27,オッズデータ入力!C$7:D$25,2,FALSE) | F27: 1 | G27: =VLOOKUP(F27,オッズデータ入力!AA$7:AB$25,2,FALSE) | H27: 1 | I27: =VLOOKUP(H27,オッズデータ入力!AM$7:AN$25,2,FALSE) | L27: =IF(B27<=2,"A",IF(B27<=5,"B",IF(B27<=7,"C",IF(B27<=10,"D",IF(B27<=13,"E",IF(B27<=16,"F",IF(B27<=18,"G"))))))) | N27: =IF(F27<=2,"A",IF(F27<=5,"B",IF(F27<=7,"C",IF(F27<=10,"D",IF(F27<=13,"E",IF(F27<=16,"F",IF(F27<=18,"G"))))))) | O27: =IF(H27<=2,"A",IF(H27<=5,"B",IF(H27<=7,"C",IF(H27<=10,"D",IF(H27<=13,"E",IF(H27<=16,"F",IF(H27<=18,"G"))))))) | Q27: =C27 | S27: =G27 | T27: =I27 | V27: 14~20 | W27: =SUM(B27,D27,F27,H27,J27) | X27: +
A28: 26 | B28: 1 | C28: =VLOOKUP(B28,オッズデータ入力!C$7:D$25,2,FALSE) | F28: 1 | G28: =VLOOKUP(F28,オッズデータ入力!AA$7:AB$25,2,FALSE) | H28: 2 | I28: =VLOOKUP(H28,オッズデータ入力!AM$7:AN$25,2,FALSE) | L28: =IF(B28<=2,"A",IF(B28<=5,"B",IF(B28<=7,"C",IF(B28<=10,"D",IF(B28<=13,"E",IF(B28<=16,"F",IF(B28<=18,"G"))))))) | N28: =IF(F28<=2,"A",IF(F28<=5,"B",IF(F28<=7,"C",IF(F28<=10,"D",IF(F28<=13,"E",IF(F28<=16,"F",IF(F28<=18,"G"))))))) | O28: =IF(H28<=2,"A",IF(H28<=5,"B",IF(H28<=7,"C",IF(H28<=10,"D",IF(H28<=13,"E",IF(H28<=16,"F",IF(H28<=18,"G"))))))) | Q28: =C28 | S28: =G28 | T28: =I28 | V28: 14~20 | W28: =SUM(B28,D28,F28,H28,J28) | X28: +
A29: 27 | B29: 1 | C29: =VLOOKUP(B29,オッズデータ入力!C$7:D$25,2,FALSE) | F29: 2 | G29: =VLOOKUP(F29,オッズデータ入力!AA$7:AB$25,2,FALSE) | H29: 1 | I29: =VLOOKUP(H29,オッズデータ入力!AM$7:AN$25,2,FALSE) | L29: =IF(B29<=2,"A",IF(B29<=5,"B",IF(B29<=7,"C",IF(B29<=10,"D",IF(B29<=13,"E",IF(B29<=16,"F",IF(B29<=18,"G"))))))) | N29: =IF(F29<=2,"A",IF(F29<=5,"B",IF(F29<=7,"C",IF(F29<=10,"D",IF(F29<=13,"E",IF(F29<=16,"F",IF(F29<=18,"G"))))))) | O29: =IF(H29<=2,"A",IF(H29<=5,"B",IF(H29<=7,"C",IF(H29<=10,"D",IF(H29<=13,"E",IF(H29<=16,"F",IF(H29<=18,"G"))))))) | Q29: =C29 | S29: =G29 | T29: =I29 | V29: 14~20 | W29: =SUM(B29,D29,F29,H29,J29) | X29: +
A30: 28 | B30: 1 | C30: =VLOOKUP(B30,オッズデータ入力!C$7:D$25,2,FALSE) | F30: 2 | G30: =VLOOKUP(F30,オッズデータ入力!AA$7:AB$25,2,FALSE) | H30: 2 | I30: =VLOOKUP(H30,オッズデータ入力!AM$7:AN$25,2,FALSE) | L30: =IF(B30<=2,"A",IF(B30<=5,"B",IF(B30<=7,"C",IF(B30<=10,"D",IF(B30<=13,"E",IF(B30<=16,"F",IF(B30<=18,"G"))))))) | N30: =IF(F30<=2,"A",IF(F30<=5,"B",IF(F30<=7,"C",IF(F30<=10,"D",IF(F30<=13,"E",IF(F30<=16,"F",IF(F30<=18,"G"))))))) | O30: =IF(H30<=2,"A",IF(H30<=5,"B",IF(H30<=7,"C",IF(H30<=10,"D",IF(H30<=13,"E",IF(H30<=16,"F",IF(H30<=18,"G"))))))) | Q30: =C30 | S30: =G30 | T30: =I30 | V30: 14~20 | W30: =SUM(B30,D30,F30,H30,J30) | X30: +
A31: 29 | B31: 2 | C31: =VLOOKUP(B31,オッズデータ入力!C$7:D$25,2,FALSE) | F31: 1 | G31: =VLOOKUP(F31,オッズデータ入力!AA$7:AB$25,2,FALSE) | H31: 1 | I31: =VLOOKUP(H31,オッズデータ入力!AM$7:AN$25,2,FALSE) | L31: =IF(B31<=2,"A",IF(B31<=5,"B",IF(B31<=7,"C",IF(B31<=10,"D",IF(B31<=13,"E",IF(B31<=16,"F",IF(B31<=18,"G"))))))) | N31: =IF(F31<=2,"A",IF(F31<=5,"B",IF(F31<=7,"C",IF(F31<=10,"D",IF(F31<=13,"E",IF(F31<=16,"F",IF(F31<=18,"G"))))))) | O31: =IF(H31<=2,"A",IF(H31<=5,"B",IF(H31<=7,"C",IF(H31<=10,"D",IF(H31<=13,"E",IF(H31<=16,"F",IF(H31<=18,"G"))))))) | Q31: =C31 | S31: =G31 | T31: =I31 | V31: 14~20 | W31: =SUM(B31,D31,F31,H31,J31) | X31: +
A32: 30 | B32: 2 | C32: =VLOOKUP(B32,オッズデータ入力!C$7:D$25,2,FALSE) | F32: 1 | G32: =VLOOKUP(F32,オッズデータ入力!AA$7:AB$25,2,FALSE) | H32: 2 | I32: =VLOOKUP(H32,オッズデータ入力!AM$7:AN$25,2,FALSE) | L32: =IF(B32<=2,"A",IF(B32<=5,"B",IF(B32<=7,"C",IF(B32<=10,"D",IF(B32<=13,"E",IF(B32<=16,"F",IF(B32<=18,"G"))))))) | N32: =IF(F32<=2,"A",IF(F32<=5,"B",IF(F32<=7,"C",IF(F32<=10,"D",IF(F32<=13,"E",IF(F32<=16,"F",IF(F32<=18,"G"))))))) | O32: =IF(H32<=2,"A",IF(H32<=5,"B",IF(H32<=7,"C",IF(H32<=10,"D",IF(H32<=13,"E",IF(H32<=16,"F",IF(H32<=18,"G"))))))) | Q32: =C32 | S32: =G32 | T32: =I32 | V32: 14~20 | W32: =SUM(B32,D32,F32,H32,J32) | X32: +
A33: 31 | B33: 2 | C33: =VLOOKUP(B33,オッズデータ入力!C$7:D$25,2,FALSE) | F33: 2 | G33: =VLOOKUP(F33,オッズデータ入力!AA$7:AB$25,2,FALSE) | H33: 1 | I33: =VLOOKUP(H33,オッズデータ入力!AM$7:AN$25,2,FALSE) | L33: =IF(B33<=2,"A",IF(B33<=5,"B",IF(B33<=7,"C",IF(B33<=10,"D",IF(B33<=13,"E",IF(B33<=16,"F",IF(B33<=18,"G"))))))) | N33: =IF(F33<=2,"A",IF(F33<=5,"B",IF(F33<=7,"C",IF(F33<=10,"D",IF(F33<=13,"E",IF(F33<=16,"F",IF(F33<=18,"G"))))))) | O33: =IF(H33<=2,"A",IF(H33<=5,"B",IF(H33<=7,"C",IF(H33<=10,"D",IF(H33<=13,"E",IF(H33<=16,"F",IF(H33<=18,"G"))))))) | Q33: =C33 | S33: =G33 | T33: =I33 | V33: 14~20 | W33: =SUM(B33,D33,F33,H33,J33) | X33: +
A34: 32 | B34: 2 | C34: =VLOOKUP(B34,オッズデータ入力!C$7:D$25,2,FALSE) | F34: 2 | G34: =VLOOKUP(F34,オッズデータ入力!AA$7:AB$25,2,FALSE) | H34: 2 | I34: =VLOOKUP(H34,オッズデータ入力!AM$7:AN$25,2,FALSE) | L34: =IF(B34<=2,"A",IF(B34<=5,"B",IF(B34<=7,"C",IF(B34<=10,"D",IF(B34<=13,"E",IF(B34<=16,"F",IF(B34<=18,"G"))))))) | N34: =IF(F34<=2,"A",IF(F34<=5,"B",IF(F34<=7,"C",IF(F34<=10,"D",IF(F34<=13,"E",IF(F34<=16,"F",IF(F34<=18,"G"))))))) | O34: =IF(H34<=2,"A",IF(H34<=5,"B",IF(H34<=7,"C",IF(H34<=10,"D",IF(H34<=13,"E",IF(H34<=16,"F",IF(H34<=18,"G"))))))) | Q34: =C34 | S34: =G34 | T34: =I34 | V34: 14~20 | W34: =SUM(B34,D34,F34,H34,J34) | X34: +
A35: 33 | B35: 1 | C35: =VLOOKUP(B35,オッズデータ入力!C$7:D$25,2,FALSE) | F35: 1 | G35: =VLOOKUP(F35,オッズデータ入力!AA$7:AB$25,2,FALSE) | J35: 1 | K35: =VLOOKUP(J35,オッズデータ入力!AY$7:AZ$25,2,FALSE) | L35: =IF(B35<=2,"A",IF(B35<=5,"B",IF(B35<=7,"C",IF(B35<=10,"D",IF(B35<=13,"E",IF(B35<=16,"F",IF(B35<=18,"G"))))))) | N35: =IF(F35<=2,"A",IF(F35<=5,"B",IF(F35<=7,"C",IF(F35<=10,"D",IF(F35<=13,"E",IF(F35<=16,"F",IF(F35<=18,"G"))))))) | P35: =IF(J35<=2,"A",IF(J35<=5,"B",IF(J35<=7,"C",IF(J35<=10,"D",IF(J35<=13,"E",IF(J35<=16,"F",IF(J35<=18,"G"))))))) | Q35: =C35 | S35: =G35 | U35: =K35 | V35: 14~20 | W35: =SUM(B35,D35,F35,H35,J35) | X35: +
A36: 34 | B36: 1 | C36: =VLOOKUP(B36,オッズデータ入力!C$7:D$25,2,FALSE) | F36: 1 | G36: =VLOOKUP(F36,オッズデータ入力!AA$7:AB$25,2,FALSE) | J36: 2 | K36: =VLOOKUP(J36,オッズデータ入力!AY$7:AZ$25,2,FALSE) | L36: =IF(B36<=2,"A",IF(B36<=5,"B",IF(B36<=7,"C",IF(B36<=10,"D",IF(B36<=13,"E",IF(B36<=16,"F",IF(B36<=18,"G"))))))) | N36: =IF(F36<=2,"A",IF(F36<=5,"B",IF(F36<=7,"C",IF(F36<=10,"D",IF(F36<=13,"E",IF(F36<=16,"F",IF(F36<=18,"G"))))))) | P36: =IF(J36<=2,"A",IF(J36<=5,"B",IF(J36<=7,"C",IF(J36<=10,"D",IF(J36<=13,"E",IF(J36<=16,"F",IF(J36<=18,"G"))))))) | Q36: =C36 | S36: =G36 | U36: =K36 | V36: 14~20 | W36: =SUM(B36,D36,F36,H36,J36) | X36: +
A37: 35 | B37: 1 | C37: =VLOOKUP(B37,オッズデータ入力!C$7:D$25,2,FALSE) | F37: 2 | G37: =VLOOKUP(F37,オッズデータ入力!AA$7:AB$25,2,FALSE) | J37: 1 | K37: =VLOOKUP(J37,オッズデータ入力!AY$7:AZ$25,2,FALSE) | L37: =IF(B37<=2,"A",IF(B37<=5,"B",IF(B37<=7,"C",IF(B37<=10,"D",IF(B37<=13,"E",IF(B37<=16,"F",IF(B37<=18,"G"))))))) | N37: =IF(F37<=2,"A",IF(F37<=5,"B",IF(F37<=7,"C",IF(F37<=10,"D",IF(F37<=13,"E",IF(F37<=16,"F",IF(F37<=18,"G"))))))) | P37: =IF(J37<=2,"A",IF(J37<=5,"B",IF(J37<=7,"C",IF(J37<=10,"D",IF(J37<=13,"E",IF(J37<=16,"F",IF(J37<=18,"G"))))))) | Q37: =C37 | S37: =G37 | U37: =K37 | V37: 14~20 | W37: =SUM(B37,D37,F37,H37,J37) | X37: +
A38: 36 | B38: 1 | C38: =VLOOKUP(B38,オッズデータ入力!C$7:D$25,2,FALSE) | F38: 2 | G38: =VLOOKUP(F38,オッズデータ入力!AA$7:AB$25,2,FALSE) | J38: 2 | K38: =VLOOKUP(J38,オッズデータ入力!AY$7:AZ$25,2,FALSE) | L38: =IF(B38<=2,"A",IF(B38<=5,"B",IF(B38<=7,"C",IF(B38<=10,"D",IF(B38<=13,"E",IF(B38<=16,"F",IF(B38<=18,"G"))))))) | N38: =IF(F38<=2,"A",IF(F38<=5,"B",IF(F38<=7,"C",IF(F38<=10,"D",IF(F38<=13,"E",IF(F38<=16,"F",IF(F38<=18,"G"))))))) | P38: =IF(J38<=2,"A",IF(J38<=5,"B",IF(J38<=7,"C",IF(J38<=10,"D",IF(J38<=13,"E",IF(J38<=16,"F",IF(J38<=18,"G"))))))) | Q38: =C38 | S38: =G38 | U38: =K38 | V38: 14~20 | W38: =SUM(B38,D38,F38,H38,J38) | X38: +
A39: 37 | B39: 2 | C39: =VLOOKUP(B39,オッズデータ入力!C$7:D$25,2,FALSE) | F39: 1 | G39: =VLOOKUP(F39,オッズデータ入力!AA$7:AB$25,2,FALSE) | J39: 1 | K39: =VLOOKUP(J39,オッズデータ入力!AY$7:AZ$25,2,FALSE) | L39: =IF(B39<=2,"A",IF(B39<=5,"B",IF(B39<=7,"C",IF(B39<=10,"D",IF(B39<=13,"E",IF(B39<=16,"F",IF(B39<=18,"G"))))))) | N39: =IF(F39<=2,"A",IF(F39<=5,"B",IF(F39<=7,"C",IF(F39<=10,"D",IF(F39<=13,"E",IF(F39<=16,"F",IF(F39<=18,"G"))))))) | P39: =IF(J39<=2,"A",IF(J39<=5,"B",IF(J39<=7,"C",IF(J39<=10,"D",IF(J39<=13,"E",IF(J39<=16,"F",IF(J39<=18,"G"))))))) | Q39: =C39 | S39: =G39 | U39: =K39 | V39: 14~20 | W39: =SUM(B39,D39,F39,H39,J39) | X39: +
A40: 38 | B40: 2 | C40: =VLOOKUP(B40,オッズデータ入力!C$7:D$25,2,FALSE) | F40: 1 | G40: =VLOOKUP(F40,オッズデータ入力!AA$7:AB$25,2,FALSE) | J40: 2 | K40: =VLOOKUP(J40,オッズデータ入力!AY$7:AZ$25,2,FALSE) | L40: =IF(B40<=2,"A",IF(B40<=5,"B",IF(B40<=7,"C",IF(B40<=10,"D",IF(B40<=13,"E",IF(B40<=16,"F",IF(B40<=18,"G"))))))) | N40: =IF(F40<=2,"A",IF(F40<=5,"B",IF(F40<=7,"C",IF(F40<=10,"D",IF(F40<=13,"E",IF(F40<=16,"F",IF(F40<=18,"G"))))))) | P40: =IF(J40<=2,"A",IF(J40<=5,"B",IF(J40<=7,"C",IF(J40<=10,"D",IF(J40<=13,"E",IF(J40<=16,"F",IF(J40<=18,"G"))))))) | Q40: =C40 | S40: =G40 | U40: =K40 | V40: 14~20 | W40: =SUM(B40,D40,F40,H40,J40) | X40: +
A41: 39 | B41: 2 | C41: =VLOOKUP(B41,オッズデータ入力!C$7:D$25,2,FALSE) | F41: 2 | G41: =VLOOKUP(F41,オッズデータ入力!AA$7:AB$25,2,FALSE) | J41: 1 | K41: =VLOOKUP(J41,オッズデータ入力!AY$7:AZ$25,2,FALSE) | L41: =IF(B41<=2,"A",IF(B41<=5,"B",IF(B41<=7,"C",IF(B41<=10,"D",IF(B41<=13,"E",IF(B41<=16,"F",IF(B41<=18,"G"))))))) | N41: =IF(F41<=2,"A",IF(F41<=5,"B",IF(F41<=7,"C",IF(F41<=10,"D",IF(F41<=13,"E",IF(F41<=16,"F",IF(F41<=18,"G"))))))) | P41: =IF(J41<=2,"A",IF(J41<=5,"B",IF(J41<=7,"C",IF(J41<=10,"D",IF(J41<=13,"E",IF(J41<=16,"F",IF(J41<=18,"G"))))))) | Q41: =C41 | S41: =G41 | U41: =K41 | V41: 14~20 | W41: =SUM(B41,D41,F41,H41,J41) | X41: +
...

Sheet 127812
A2: 1 | B2: 45585 | C2: 1 | D2: 1 | E2: 7 | F2: 12 | G2: 13 | H2: 1 | I2: 1 | J2: 1 | K2: 8 | L2: 2 | M2: 745990 | N2: 631 | O2: 13 | P2: =VLOOKUP(C2,オッズデータ入力!C$7:C$25,2,FALSE) | Q2: =VLOOKUP(D2,オッズデータ入力!O$7:P$25,2,FALSE) | R2: =VLOOKUP(E2,オッズデータ入力!AA$8:AB$25,2,FALSE) | S2: =VLOOKUP(F2,オッズデータ入力!AM$8:AN$25,2,FALSE) | T2: =VLOOKUP(G2,オッズデータ入力!AY$8:AZ$25,2,FALSE) | U2: =SUM(P2:T2) | V2: A | W2: A | X2: A | Y2: D | Z2: A | AA2: 4 | AB2: 0 | AC2: 0 | AD2: 1 | AE2: 0 | AF2: 0 | AG2: 0 | AH2: AAADA | AI2: 5 | AJ2: 1-1-1-8-2 | AK2: 1
A3: 2 | B3: 44641 | C3: 2 | D3: 1 | E3: 7 | F3: 13 | G3: 1 | H3: 4 | I3: 1 | J3: 1 | K3: 1 | L3: 2 | M3: 72230 | N3: 6821 | O3: 9 | P3: =VLOOKUP(C3,オッズデータ入力!C$7:C$25,2,FALSE) | Q3: =VLOOKUP(D3,オッズデータ入力!O$7:P$25,2,FALSE) | R3: =VLOOKUP(E3,オッズデータ入力!AA$8:AB$25,2,FALSE) | S3: =VLOOKUP(F3,オッズデータ入力!AM$8:AN$25,2,FALSE) | T3: =VLOOKUP(G3,オッズデータ入力!AY$8:AZ$25,2,FALSE) | U3: =SUM(P3:T3) | V3: B | W3: A | X3: A | Y3: A | Z3: A | AA3: 4 | AB3: 1 | AC3: 0 | AD3: 0 | AE3: 0 | AF3: 0 | AG3: 0 | AH3: BAAAA | AI3: 5 | AJ3: 4-1-1-1-2 | AK3: 1
A4: 3 | B4: 41287 | C4: 8 | D4: 2 | E4: 13 | F4: 8 | G4: 2 | H4: 1 | I4: 2 | J4: 1 | K4: 1 | L4: 10 | M4: 384580 | N4: 1410 | O4: 15 | P4: =VLOOKUP(C4,オッズデータ入力!C$7:C$25,2,FALSE) | Q4: =VLOOKUP(D4,オッズデータ入力!O$7:P$25,2,FALSE) | R4: =VLOOKUP(E4,オッズデータ入力!AA$8:AB$25,2,FALSE) | S4: =VLOOKUP(F4,オッズデータ入力!AM$8:AN$25,2,FALSE) | T4: =VLOOKUP(G4,オッズデータ入力!AY$8:AZ$25,2,FALSE) | U4: =SUM(P4:T4) | V4: A | W4: A | X4: A | Y4: A | Z4: D | AA4: 4 | AB4: 0 | AC4: 0 | AD4: 1 | AE4: 0 | AF4: 0 | AG4: 0 | AH4: AAAAD | AI4: 3 | AJ4: 1-2-1-1-10 | AK4: 1
A5: 4 | B5: 45718 | C5: 8 | D5: 1 | E5: 12 | F5: 2 | G5: 1 | H5: 2 | I5: 2 | J5: 8 | K5: 9 | L5: 2 | M5: 4962620 | N5: 128 | O5: 23 | P5: =VLOOKUP(C5,オッズデータ入力!C$7:C$25,2,FALSE) | Q5: =VLOOKUP(D5,オッズデータ入力!O$7:P$25,2,FALSE) | R5: =VLOOKUP(E5,オッズデータ入力!AA$8:AB$25,2,FALSE) | S5: =VLOOKUP(F5,オッズデータ入力!AM$8:AN$25,2,FALSE) | T5: =VLOOKUP(G5,オッズデータ入力!AY$8:AZ$25,2,FALSE) | U5: =SUM(P5:T5) | V5: A | W5: A | X5: D | Y5: D | Z5: A | AA5: 3 | AB5: 0 | AC5: 0 | AD5: 2 | AE5: 0 | AF5: 0 | AG5: 0 | AH5: AADDA | AI5: 2 | AJ5: 2-2-8-9-2 | AK5: 1
A6: 5 | B6: 44045 | C6: 8 | D6: 7 | E6: 13 | F6: 1 | G6: 12 | H6: 1 | I6: 4 | J6: 2 | K6: 11 | L6: 1 | M6: 2715060 | N6: 234 | O6: 19 | P6: =VLOOKUP(C6,オッズデータ入力!C$7:C$25,2,FALSE) | Q6: =VLOOKUP(D6,オッズデータ入力!O$7:P$25,2,FALSE) | R6: =VLOOKUP(E6,オッズデータ入力!AA$8:AB$25,2,FALSE) | S6: =VLOOKUP(F6,オッズデータ入力!AM$8:AN$25,2,FALSE) | T6: =VLOOKUP(G6,オッズデータ入力!AY$8:AZ$25,2,FALSE) | U6: =SUM(P6:T6) | V6: A | W6: B | X6: A | Y6: E | Z6: A | AA6: 3 | AB6: 1 | AC6: 0 | AD6: 0 | AE6: 1 | AF6: 0 | AG6: 0 | AH6: ABAEA | AI6: 1 | AJ6: 1-4-2-11-1 | AK6: 1
A7: 6 | B7: 43009 | C7: 1 | D7: 7 | E7: 2 | F7: 12 | G7: 8 | H7: 1 | I7: 1 | J7: 8 | K7: 9 | L7: 1 | M7: 1437760 | N7: 279 | O7: 20 | P7: =VLOOKUP(C7,オッズデータ入力!C$7:C$25,2,FALSE) | Q7: =VLOOKUP(D7,オッズデータ入力!O$7:P$25,2,FALSE) | R7: =VLOOKUP(E7,オッズデータ入力!AA$8:AB$25,2,FALSE) | S7: =VLOOKUP(F7,オッズデータ入力!AM$8:AN$25,2,FALSE) | T7: =VLOOKUP(G7,オッズデータ入力!AY$8:AZ$25,2,FALSE) | U7: =SUM(P7:T7) | V7: A | W7: A | X7: D | Y7: D | Z7: A | AA7: 3 | AB7: 0 | AC7: 0 | AD7: 2 | AE7: 0 | AF7: 0 | AG7: 0 | AH7: AADDA | AI7: 2 | AJ7: 1-1-8-9-1 | AK7: 1
